<mujoco model="X2_urdf">
  <compiler angle='radian' eulerseq="XYZ" meshdir="../meshes"
    autolimits="true" />

  <option timestep="0.001" />


  <!-- <visual>
    <global ellipsoidinertia="true"/>
  </visual> -->


  <default>
      <default class="x2">
          <site rgba="1 0 0 1" size="0.01" group="5"/>
          <joint damping="0.0" armature="0.03" frictionloss="0.3"/>
          <default class="visual">
              <geom group="2" type="mesh" contype="0" conaffinity="0" density="0" material="metallic"/>
          </default>
          <default class="collision">
              <geom group="3" type="mesh"/>
              <default class="foot">
                  <geom type="sphere" size="0.005"/>
              </default>
          </default>
      </default>
  </default>

  <asset>
    <material name="metallic" rgba="0.7 0.7 0.7 1"/>
    <material name="black_transparent" rgba="0.2 0.2 0.2 0.7"/>
    <material name="black" rgba="0.2 0.2 0.2 1"/>
    <material name="white" rgba="1 1 1 1"/>
    <material name="yellow" rgba="1 0.82 0.31 1"/>
    <material name="red" rgba="1 0 0 1"/>
    <mesh name="pelvis" file="pelvis.STL"/>
    <mesh name="left_hip_pitch_link"  file="left_hip_pitch_link.STL"/>
    <mesh name="left_hip_roll_link"  file="left_hip_roll_link.STL"/>
    <mesh name="left_hip_yaw_link"  file="left_hip_yaw_link.STL"/>
    <mesh name="left_knee_link"  file="left_knee_link.STL"/>
    <mesh name="left_ankle_pitch_link"  file="left_ankle_pitch_link.STL"/>
    <mesh name="left_ankle_roll_link"  file="left_ankle_roll_link.STL"/>
    <mesh name="right_hip_pitch_link"  file="right_hip_pitch_link.STL"/>
    <mesh name="right_hip_roll_link"  file="right_hip_roll_link.STL"/>
    <mesh name="right_hip_yaw_link"  file="right_hip_yaw_link.STL"/>
    <mesh name="right_knee_link"  file="right_knee_link.STL"/>
    <mesh name="right_ankle_pitch_link"  file="right_ankle_pitch_link.STL"/>
    <mesh name="right_ankle_roll_link"  file="right_ankle_roll_link.STL"/>
    <mesh name="waist_yaw_link"  file="waist_yaw_link.STL"/>
    <mesh name="waist_pitch_link"  file="waist_pitch_link.STL"/>
    <mesh name="waist_roll_link"  file="waist_roll_link.STL"/>
    <mesh name="imu_in_torso_link"  file="imu_in_torso_link.STL"/>
    <mesh name="left_shoulder_pitch_link"  file="left_shoulder_pitch_link.STL"/>
    <mesh name="left_shoulder_roll_link"  file="left_shoulder_roll_link.STL"/>
    <mesh name="left_shoulder_yaw_link"  file="left_shoulder_yaw_link.STL"/>
    <mesh name="left_elbow_pitch_link"  file="left_elbow_pitch_link.STL"/>
    <mesh name="left_elbow_roll_link"  file="left_elbow_roll_link.STL"/>
    <mesh name="left_wrist_pitch_link"  file="left_wrist_pitch_link.STL"/>
    <mesh name="left_wrist_yaw_link"  file="left_wrist_yaw_link.STL"/>
    <mesh name="fleft_wrist_yaw_link"  file="fleft_wrist_yaw_link.STL"/>
    <mesh name="right_shoulder_pitch_link"  file="right_shoulder_pitch_link.STL"/>
    <mesh name="right_shoulder_roll_link"  file="right_shoulder_roll_link.STL"/>
    <mesh name="right_shoulder_yaw_link"  file="right_shoulder_yaw_link.STL"/>
    <mesh name="right_elbow_pitch_link"  file="right_elbow_pitch_link.STL"/>
    <mesh name="right_elbow_roll_link"  file="right_elbow_roll_link.STL"/>
    <mesh name="right_wrist_pitch_link"  file="right_wrist_pitch_link.STL"/>
    <mesh name="right_wrist_yaw_link"  file="right_wrist_yaw_link.STL"/>
    <mesh name="fright_wrist_yaw_link"  file="fright_wrist_yaw_link.STL"/>
    <mesh name="head_yaw_link" content_type="model/stl" file="head_yaw_link.STL"/>
    <mesh name="head_pitch_link" content_type="model/stl" file="head_pitch_link.STL"/>
  </asset>

  <worldbody>
    <body name="pelvis" pos="0 0 0.8" euler="0 0 0" childclass="x2">
      <light name="tracking" mode="trackcom" pos="0 0 2"/>
      <freejoint name="floating_base_joint"/>
      <geom class="visual" type="mesh" contype="0" conaffinity="0" group="1" density="0" rgba="0.2 0.2 0.2 1" mesh="pelvis"/>
      <geom class="collision" type="mesh" rgba="0.2 0.2 0.2 1" mesh="pelvis"/>
      <site name="imu_0" pos="0.0265577 -0.000120756 0.03986" group="1"/>
      <body name="left_hip_pitch_link" pos="0 0.07135 0">
        <inertial pos="0.0117082 0.0647652 6.09e-05" quat="0.772057 0.635326 -0.0106131 -0.0132734" mass="1.4085" diaginertia="0.0014363 0.0010604 0.0010011"/>
        <joint name="left_hip_pitch_joint" pos="0 0 0" axis="0 1 0" range="-2.4871 2.4871" actuatorfrcrange="-118 118"/>
        <geom class="visual"  type="mesh" contype="0" conaffinity="0" group="1" density="0" rgba="0.2 0.2 0.2 1" mesh="left_hip_pitch_link"/>
        <geom class="collision"  type="mesh"  rgba="0.2 0.2 0.2 1" mesh="left_hip_pitch_link"/>
        <body name="left_hip_roll_link" pos="-0.000773306 0.0657 0">
          <inertial pos="2.32e-05 0.0002946 -0.0981279" quat="0.708196 -0.0064169 -0.0036351 0.705978" mass="1.62981" diaginertia="0.00383613 0.00332276 0.001985"/>
          <joint name="left_hip_roll_joint" pos="0 0 0" axis="1 0 0" range="-0.12217 2.9059" actuatorfrcrange="-118 118"/>
          <geom class="visual"  type="mesh" contype="0" conaffinity="0" group="1" density="0" rgba="1 1 1 1" mesh="left_hip_roll_link"/>
          <geom class="collision"  type="mesh" rgba="1 1 1 1" mesh="left_hip_roll_link"/>
          <body name="left_hip_yaw_link" pos="0 0 -0.13685">
            <inertial pos="-0.0028597 0.0072402 -0.144561" quat="0.779451 0.00112589 -0.0540782 0.624124" mass="1.99741" diaginertia="0.0102166 0.00965433 0.0022266"/>
            <joint name="left_hip_yaw_joint" pos="0 0 0" axis="0 0 1" range="-1.6842 3.4296" actuatorfrcrange="-118 118"/>
            <geom class="visual"  type="mesh" contype="0" conaffinity="0" group="1" density="0" rgba="1 1 1 1" mesh="left_hip_yaw_link"/>
            <geom class="collision"  type="mesh" rgba="1 1 1 1" mesh="left_hip_yaw_link"/>
            <body name="left_knee_link" pos="-0.00766 0.0004 -0.1831">
              <inertial pos="-0.0024515 0.0021926 -0.126714" quat="0.739994 -0.0261197 -0.0143143 0.671953" mass="1.67139" diaginertia="0.00790567 0.0077088 0.00214413"/>
              <joint name="left_knee_joint" pos="0 0 0" axis="0 1 0" range="-0.026179 2.1206" actuatorfrcrange="-118 118"/>
              <geom class="visual"  type="mesh" contype="0" conaffinity="0" group="1" density="0" rgba="1 1 1 1" mesh="left_knee_link"/>
              <geom class="collision"  type="mesh"  rgba="1 1 1 1" mesh="left_knee_link"/>
              <body name="left_ankle_pitch_link" pos="-0.00922669 -0.0004 -0.282">
                <inertial pos="-7.03e-05 0.0001863 3.98e-05" quat="0.512105 0.472196 0.523372 0.490776" mass="0.566557" diaginertia="0.000353604 0.000351091 0.000253806"/>
                <joint name="left_ankle_pitch_joint" pos="0 0 0" axis="0 1 0" range="-0.8029 0.45378" actuatorfrcrange="-36 36"/>
                <geom class="visual"  type="mesh" contype="0" conaffinity="0" group="1" density="0" rgba="0.2 0.2 0.2 1" mesh="left_ankle_pitch_link"/>
                <geom class="collision"  type="mesh"  rgba="0.2 0.2 0.2 1" mesh="left_ankle_pitch_link"/>
                <body name="left_ankle_roll_link" pos="-0.0002 0 0">
                  <inertial pos="0.0301062 0 -0.0497131" quat="2.13317e-05 0.703389 -2.33692e-05 0.710805" mass="0.560772" diaginertia="0.00267992 0.0022686 0.000687181"/>
                  <joint name="left_ankle_roll_joint" pos="0 0 0" axis="1 0 0" range="-0.2618 0.2618" actuatorfrcrange="-24 24"/>
                  <geom class="visual"  type="mesh" contype="0" conaffinity="0" group="1" density="0" rgba="1 0.5 0 1" mesh="left_ankle_roll_link"/>
                  <geom class="collision" type="sphere"  group="1"  size="0.005" pos="-0.05 0.05 -0.068" rgba="1 0.5 0 1"/>
                  <geom class="collision" type="sphere"   group="1" size="0.005" pos="-0.065 0.025 -0.068" rgba="1 0.5 0 1"/>
                  <geom class="collision" type="sphere"  group="1"  size="0.005" pos="-0.05 -0.05 -0.068" rgba="1 0.5 0 1"/>
                  <geom class="collision" type="sphere"  group="1"  size="0.005" pos="-0.065 -0.025 -0.068" rgba="1 0.5 0 1"/>
                  <geom class="collision" type="sphere"  group="1"  size="0.005" pos="0.11 0.05 -0.068" rgba="1 0.5 0 1"/>
                  <geom class="collision" type="sphere"  group="1"  size="0.005" pos="0.11 -0.05 -0.068" rgba="1 0.5 0 1"/>
                  <geom class="collision" type="sphere"   group="1" size="0.005" pos="-0.02 -0.06 -0.068" rgba="1 0.5 0 1"/>
                  <geom class="collision" type="sphere"  group="1"  size="0.005" pos="-0.02 0.06 -0.068" rgba="1 0.5 0 1"/>
                  <geom class="collision" type="sphere"  group="1"  size="0.005" pos="0.07 -0.06 -0.068" rgba="1 0.5 0 1"/>
                  <geom class="collision" type="sphere"   group="1" size="0.005" pos="0.07 0.06 -0.068" rgba="1 0.5 0 1"/>
                  <geom class="collision" type="sphere"  group="1"  size="0.005" pos="0.139 0 -0.066" rgba="1 0.5 0 1"/>
                  <geom class="collision" type="sphere"   group="1" size="0.005" pos="0.128 0 -0.02" rgba="1 0.5 0 1"/>
                </body>
              </body>
            </body>
          </body>
        </body>
      </body>
      <body name="right_hip_pitch_link" pos="0 -0.07135 0">
        <inertial pos="0.0115194 -0.0643558 0.0001612" quat="0.774596 0.632058 0.0116355 0.0192177" mass="1.43266" diaginertia="0.00152784 0.00111246 0.0010535"/>
        <joint name="right_hip_pitch_joint" pos="0 0 0" axis="0 1 0" range="-2.4871 2.4871" actuatorfrcrange="-118 118"/>
        <geom class="visual" type="mesh" contype="0" conaffinity="0" group="1" density="0" rgba="0.2 0.2 0.2 1" mesh="right_hip_pitch_link"/>
        <geom class="collision" type="mesh" rgba="0.2 0.2 0.2 1" mesh="right_hip_pitch_link"/>
        <body name="right_hip_roll_link" pos="-0.000575 -0.0657 0">
          <inertial pos="0.0010421 -0.0002391 -0.0968709" quat="0.705377 0.0150491 0.0129738 0.708554" mass="1.66095" diaginertia="0.00409593 0.00358339 0.00205318"/>
          <joint name="right_hip_roll_joint" pos="0 0 0" axis="1 0 0" range="-2.9059 0.12217" actuatorfrcrange="-118 118"/>
          <geom class="visual" type="mesh" contype="0" conaffinity="0" group="1" density="0" rgba="1 1 1 1" mesh="right_hip_roll_link"/>
          <geom class="collision" type="mesh" rgba="1 1 1 1" mesh="right_hip_roll_link"/>
          <body name="right_hip_yaw_link" pos="0.000575 0 -0.13685">
            <inertial pos="-0.0028354 -0.0069976 -0.141737" quat="0.684357 0.00411183 0.0519319 0.727284" mass="2.06691" diaginertia="0.0109341 0.0104347 0.002261"/>
            <joint name="right_hip_yaw_joint" pos="0 0 0" axis="0 0 1" range="-3.4296 1.6842" actuatorfrcrange="-118 118"/>
            <geom class="visual" type="mesh" contype="0" conaffinity="0" group="1" density="0" rgba="1 1 1 1" mesh="right_hip_yaw_link"/>
            <geom class="collision" type="mesh" rgba="1 1 1 1" mesh="right_hip_yaw_link"/>
            <body name="right_knee_link" pos="-0.00766 -0.000175 -0.18321">
              <inertial pos="-0.003119 -0.001969 -0.126103" quat="0.665127 -0.0148822 -0.0243749 0.746184" mass="1.67394" diaginertia="0.00790406 0.00772918 0.00213926"/>
              <joint name="right_knee_joint" pos="0 0 0" axis="0 1 0" range="-0.0262 2.1206" actuatorfrcrange="-118 118"/>
              <geom class="visual" type="mesh" contype="0" conaffinity="0" group="1" density="0" rgba="1 1 1 1" mesh="right_knee_link"/>
              <geom class="collision" type="mesh"  rgba="1 1 1 1" mesh="right_knee_link"/>
              <body name="right_ankle_pitch_link" pos="-0.0098209 0.000625 -0.28201">
                <inertial pos="-7.03e-05 0.0001863 3.98e-05" quat="0.512105 0.472196 0.523372 0.490776" mass="0.566557" diaginertia="0.000353604 0.000351091 0.000253806"/>
                <joint name="right_ankle_pitch_joint" pos="0 0 0" axis="0 1 0" range="-0.80285 0.45378" actuatorfrcrange="-36 36"/>
                <geom class="visual" type="mesh" contype="0" conaffinity="0" group="1" density="0" rgba="0.2 0.2 0.2 1" mesh="right_ankle_pitch_link"/>
                <geom class="collision" type="mesh"  rgba="0.2 0.2 0.2 1" mesh="right_ankle_pitch_link"/>
                <body name="right_ankle_roll_link" pos="-0.000289528 0 0">
                  <inertial pos="0.0301959 -0.0007743 -0.049707" quat="0.00548144 0.703367 0.00552781 0.710784" mass="0.560772" diaginertia="0.00267992 0.0022686 0.000687181"/>
                  <joint name="right_ankle_roll_joint" pos="0 0 0" axis="1 0 0" range="-0.2618 0.2618" actuatorfrcrange="-24 24"/>
                  <geom class="visual"  type="mesh" contype="0" conaffinity="0" group="1" density="0" rgba="1 0.5 0 1" mesh="right_ankle_roll_link"/>
                  <geom class="collision" type="sphere"  group="1"  size="0.005" pos="-0.05 0.05 -0.068" rgba="1 0.5 0 1"/>
                  <geom class="collision" type="sphere"  group="1"  size="0.005" pos="-0.065 0.025 -0.068" rgba="1 0.5 0 1"/>
                  <geom class="collision" type="sphere"  group="1" size="0.005" pos="-0.05 -0.05 -0.068" rgba="1 0.5 0 1"/>
                  <geom class="collision" type="sphere"  group="1" size="0.005" pos="-0.065 -0.025 -0.068" rgba="1 0.5 0 1"/>
                  <geom class="collision" type="sphere"  group="1"  size="0.005" pos="0.11 0.05 -0.068" rgba="1 0.5 0 1"/>
                  <geom class="collision" type="sphere"  group="1" size="0.005" pos="0.11 -0.05 -0.068" rgba="1 0.5 0 1"/>
                  <geom class="collision" type="sphere"  group="1" size="0.005" pos="-0.02 -0.06 -0.068" rgba="1 0.5 0 1"/>
                  <geom class="collision" type="sphere"  group="1"  size="0.005" pos="-0.02 0.06 -0.068" rgba="1 0.5 0 1"/>
                  <geom class="collision" type="sphere"  group="1"  size="0.005" pos="0.07 -0.06 -0.068" rgba="1 0.5 0 1"/>
                  <geom class="collision" type="sphere"  group="1" size="0.005" pos="0.07 0.06 -0.068" rgba="1 0.5 0 1"/>
                  <geom class="collision" type="sphere"  group="1"  size="0.005" pos="0.139 0 -0.066" rgba="1 0.5 0 1"/>
                  <geom class="collision" type="sphere"  group="1"  size="0.005" pos="0.128 0 -0.02" rgba="1 0.5 0 1"/>
                </body>
              </body>
            </body>
          </body>
        </body>
      </body>
      <body name="waist_yaw_link" pos="0 0 0.06825">
        <inertial pos="-0.0008218 -4.25e-05 0.0331227" quat="0.62158 0.604926 -0.35037 0.353475" mass="1.55279" diaginertia="0.00211956 0.00197151 0.00191333"/>
        <joint name="waist_yaw_joint" pos="0 0 0" axis="0 0 1" range="-2.3824 3.4296" actuatorfrcrange="-118 118"/>
        <geom class="visual"  type="mesh" contype="0" conaffinity="0" group="1" density="0" rgba="0.2 0.2 0.2 1" mesh="waist_yaw_link"/>
        <!-- <geom class="collision"  type="mesh"  rgba="0.2 0.2 0.2 1" mesh="waist_yaw_link"/> -->
        <body name="waist_pitch_link" pos="0 0 0.0871">
          <inertial pos="0.0007603 -0.0014612 0" quat="0.707103 0.707103 0.00239682 0.00239682" mass="0.127458" diaginertia="3.72014e-05 3.6e-05 7.69864e-06"/>
          <joint name="waist_pitch_joint" pos="0 0 0" axis="0 1 0" range="-0.3142 0.3142" actuatorfrcrange="-48 48"/>
          <geom class="visual"  type="mesh" contype="0" conaffinity="0" group="1" density="0" rgba="0.2 0.2 0.2 1" mesh="waist_pitch_link"/>
          <!-- <geom class="collision"  type="mesh"  rgba="0.2 0.2 0.2 1" mesh="waist_pitch_link"/> -->
          <body name="waist_roll_link">
            <inertial pos="-0.00747711 0.000145623 0.232836" quat="0.999986 0.00331037 -0.00413571 -0.000366238" mass="11.4233" diaginertia="0.173852 0.15612 0.0792604"/>
            <joint name="waist_roll_joint" pos="0 0 0" axis="1 0 0" range="-0.48869 0.48869" actuatorfrcrange="-48 48"/>
            <geom class="visual"  type="mesh" contype="0" conaffinity="0" group="1" density="0" rgba="1 1 1 1" mesh="waist_roll_link"/>
            <geom class="collision"  type="mesh" rgba="1 1 1 1" mesh="waist_roll_link"/>
            <geom class="visual"  pos="0.00799948 0 0.3963" quat="1 0 0 0" type="mesh" contype="0" conaffinity="0" group="1" density="0" rgba="0.2 0.2 0.2 1" mesh="head_yaw_link"/>
            <geom class="collision" pos="0.00799948 0 0.3963" type="mesh"  rgba="0.2 0.2 0.2 1" mesh="head_yaw_link"/>
            <geom class="visual"  pos="0.00799948 0 0.3963" quat="1 0 0 0" type="mesh" contype="0" conaffinity="0" group="1" density="0" rgba="0 0 0 0.6" mesh="head_pitch_link"/>
            <geom class="collision" pos="0.00799948 0 0.3963" type="mesh"  rgba="0 0 0 0.6" mesh="head_pitch_link"/>
            <site name="imu_1" pos="0.0265577 -0.000120756 0.03986" group="1"/>
            <body name="head_yaw_link" pos="0.00799948 0 0.3963">
              <inertial pos="-0.0123632 -0.0009517 -0.0455472" quat="0.380582 0.881571 0.0709907 -0.270092" mass="0.540482" diaginertia="0.00160247 0.00116002 0.00115211"/>
              <joint name="head_yaw_joint" pos="0 0 0" axis="0 0 1" range="-0.5236 0.5236" actuatorfrcrange="-2.6 2.6"/>
              <geom class="visual" type="mesh" contype="0" conaffinity="0" group="1" density="0" rgba="0.2 0.2 0.2 1" mesh="head_yaw_link"/>
              <!-- <geom class="collision" type="mesh" rgba="0.2 0.2 0.2 1" mesh="head_yaw_link"/> -->
              <body name="head_pitch_link">
                <inertial pos="0.0041271 -0.0013985 0.0075632" quat="0.351029 0.6099 0.602274 0.376916" mass="1.46044" diaginertia="0.00537678 0.00470613 0.00454529"/>
                <joint name="head_pitch_joint" pos="0 0 0" axis="0 1 0" range="-0.5236 0.5236" actuatorfrcrange="-0.6 0.6"/>
                <geom class="visual" type="mesh" contype="0" conaffinity="0" group="1" density="0" rgba="0 0 0 0.6" mesh="head_pitch_link"/>
                <!-- <geom class="collision" type="mesh" rgba="0 0 0 0.6" mesh="head_pitch_link"/> -->
              </body>
            </body>
            <body name="left_shoulder_pitch_link" pos="0.006 0.142739 0.24159" quat="0.994522 0.104528 0 0">
              <inertial pos="0.0023376 0.0510704 1.64e-05" quat="0.720009 0.693814 0.0112577 0.00907681" mass="0.835512" diaginertia="0.000714899 0.000607514 0.000596387"/>
              <joint name="left_shoulder_pitch_joint" pos="0 0 0" axis="0 1 0" range="-2.5569 2.5569" actuatorfrcrange="-36 36"/>
              <geom class="visual"  type="mesh" contype="0" conaffinity="0" group="1" density="0" rgba="0.2 0.2 0.2 1" mesh="left_shoulder_pitch_link"/>
              <geom class="collision"  type="mesh"  rgba="0.2 0.2 0.2 1" mesh="left_shoulder_pitch_link"/>
              <body name="left_shoulder_roll_link" pos="-0.0005 0.0495 0">
                <inertial pos="0.0001884 -3.53e-05 -0.0783721" quat="0.705983 -0.0216829 -0.0160804 0.707714" mass="0.699569" diaginertia="0.00117954 0.00108316 0.000569297"/>
                <joint name="left_shoulder_roll_joint" pos="0 0 0" axis="1 0 0" range="-0.06108 3.3598" actuatorfrcrange="-36 36"/>
                <geom class="visual"  type="mesh" contype="0" conaffinity="0" group="1" density="0" rgba="1 1 1 1" mesh="left_shoulder_roll_link"/>
                <geom class="collision"  type="mesh" rgba="1 1 1 1" mesh="left_shoulder_roll_link"/>
                <body name="left_shoulder_yaw_link" pos="0.0005 0 -0.1212">
                  <inertial pos="0.0099905 0.0003444 -0.0889032" quat="0.993305 -0.00355859 -0.11158 0.0296984" mass="0.628111" diaginertia="0.000902442 0.000872292 0.000410066"/>
                  <joint name="left_shoulder_yaw_joint" pos="0 0 0" axis="0 0 1" range="-2.5569 2.5569" actuatorfrcrange="-24 24"/>
                  <geom class="visual"  type="mesh" contype="0" conaffinity="0" group="1" density="0" rgba="1 1 1 1" mesh="left_shoulder_yaw_link"/>
                  <geom class="collision"  type="mesh"  rgba="1 1 1 1" mesh="left_shoulder_yaw_link"/>
                  <body name="left_elbow_pitch_link" pos="0.014 0.0002 -0.103" quat="0.707108 9.0274e-07 0.707106 9.0274e-07">
                    <inertial pos="0.0835945 0.0006479 -0.0146691" quat="0.0417099 0.730951 -0.0820824 0.67619" mass="0.676674" diaginertia="0.000734353 0.000709408 0.000438639"/>
                    <joint name="left_elbow_pitch_joint" pos="0 0 0" axis="0 1 0" range="-2.4435 0" actuatorfrcrange="-24 24"/>
                    <geom class="visual" type="mesh" contype="0" conaffinity="0" group="1" density="0" rgba="1 1 1 1" mesh="left_elbow_pitch_link"/>
                    <geom class="collision"  type="mesh" rgba="1 1 1 1" mesh="left_elbow_pitch_link"/>
                    <body name="left_elbow_roll_link" pos="0.120694 -0.00019755 -0.014">
                      <inertial pos="0.0314471 0.0037944 0.0005932" quat="-0.167022 0.681963 0.106501 0.70405" mass="0.309904" diaginertia="0.00022583 0.00019307 0.000166901"/>
                      <joint name="left_elbow_roll_joint" pos="0 0 0" axis="1 0 0" range="-2.5569 2.5569" actuatorfrcrange="-24 24"/>
                      <geom class="visual" type="mesh" contype="0" conaffinity="0" group="1" density="0" rgba="1 1 1 1" mesh="left_elbow_roll_link"/>
                      <geom class="collision"  type="mesh" rgba="1 1 1 1" mesh="left_elbow_roll_link"/>
                      <body name="left_wrist_pitch_link" pos="0.0803 0 0">
                        <inertial pos="-0.0002851 -1.5e-05 -0.0005068" quat="0.997848 0 -0.0655678 0" mass="0.219414" diaginertia="6.47376e-05 6.41e-05 5.08624e-05"/>
                        <joint name="left_wrist_pitch_joint" pos="0 0 0" axis="0 1 0" range="-0.5585 0.5585" actuatorfrcrange="-2.2 2.2"/>
                        <geom class="visual" type="mesh" contype="0" conaffinity="0" group="1" density="0" rgba="0.2 0.2 0.2 1" mesh="left_wrist_pitch_link"/>
                        <!-- <geom class="collision"  type="mesh" rgba="0.2 0.2 0.2 1" mesh="left_wrist_pitch_link"/> -->
                        <body name="left_wrist_yaw_link">
                          <inertial pos="0.029964 1.06831e-08 0.0197564" quat="0 0.859249 0 0.511558" mass="0.017137" diaginertia="1.40313e-05 1.4e-05 3.76872e-06"/>
                          <joint name="left_wrist_yaw_joint" pos="0 0 0" axis="0 0 1" range="-1.5446 1.5446" actuatorfrcrange="-2.2 2.2"/>
                          <geom class="visual" pos="0 0 0" quat="0.707107 -2.62646e-05 -0.707107 7.20094e-05" type="mesh" contype="0" conaffinity="0" group="1" density="0" rgba="1 1 1 1" mesh="fleft_wrist_yaw_link"/>
                          <geom class="collision" pos="0 0 0" quat="0.707107 -2.62646e-05 -0.707107 7.20094e-05" type="mesh" rgba="1 1 1 1" mesh="fleft_wrist_yaw_link"/>
                        </body>
                      </body>
                    </body>
                  </body>
                </body>
              </body>
            </body>
            <body name="right_shoulder_pitch_link" pos="0.006 -0.14274 0.24159" quat="0.994522 -0.104529 0 0">
              <inertial pos="0.0017977 -0.049031 -2.57e-05" quat="0.999865 0.01258 -0.00275698 0.0101813" mass="0.7837" diaginertia="0.000619536 0.000540485 0.000513079"/>
              <joint name="right_shoulder_pitch_joint" pos="0 0 0" axis="0 1 0" range="-2.5569 2.5569" actuatorfrcrange="-36 36"/>
              <geom class="visual"  type="mesh" contype="0" conaffinity="0" group="1" density="0" rgba="0.2 0.2 0.2 1" mesh="right_shoulder_pitch_link"/>
              <geom class="collision"  type="mesh" rgba="0.2 0.2 0.2 1" mesh="right_shoulder_pitch_link"/>
              <body name="right_shoulder_roll_link" pos="-0.0005 -0.0495 0">
                <inertial pos="0.0004783 4.54e-05 -0.0819375" quat="0.707723 -0.00285135 -0.00838178 0.706435" mass="0.691107" diaginertia="0.00106004 0.000968125 0.000471039"/>
                <joint name="right_shoulder_roll_joint" pos="0 0 0" axis="1 0 0" range="-3.3598 0.0611" actuatorfrcrange="-36 36"/>
                <geom class="visual"  type="mesh" contype="0" conaffinity="0" group="1" density="0" rgba="1 1 1 1" mesh="right_shoulder_roll_link"/>
                <geom class="collision"  type="mesh" rgba="1 1 1 1" mesh="right_shoulder_roll_link"/>
                <body name="right_shoulder_yaw_link" pos="0.0005 0 -0.1212">
                  <inertial pos="0.0100077 -0.0034388 -0.0889044" quat="0.946161 -0.00837946 -0.113945 0.302864" mass="0.627856" diaginertia="0.000797954 0.000772692 0.000296754"/>
                  <joint name="right_shoulder_yaw_joint" pos="0 0 0" axis="0 0 1" range="-2.5569 2.5569" actuatorfrcrange="-24 24"/>
                  <geom class="visual"  type="mesh" contype="0" conaffinity="0" group="1" density="0" rgba="1 1 1 1" mesh="right_shoulder_yaw_link"/>
                  <geom class="collision"  type="mesh"  rgba="1 1 1 1" mesh="right_shoulder_yaw_link"/>
                  <body name="right_elbow_pitch_link" pos="0.014 -0.0001 -0.103" quat="0.707101 -0.00286688 0.707101 0.00286686">
                    <inertial pos="0.0876472 -0.0009386 -0.0148346" quat="0.0676658 0.64322 0.155903 0.746581" mass="0.607887" diaginertia="0.000529157 0.000503797 0.000277647"/>
                    <joint name="right_elbow_pitch_joint" pos="0 0 0" axis="0 1 0" range="-2.4435 0" actuatorfrcrange="-24 24"/>
                    <geom class="visual" type="mesh" contype="0" conaffinity="0" group="1" density="0" rgba="1 1 1 1" mesh="right_elbow_pitch_link"/>
                    <geom class="collision" type="mesh" rgba="1 1 1 1" mesh="right_elbow_pitch_link"/>
                    <body name="right_elbow_roll_link" pos="0.120694 9.75482e-05 -0.014">
                      <inertial pos="0.0314483 -0.0024264 0.0005932" quat="0.169504 0.684261 -0.0902627 0.703497" mass="0.309688" diaginertia="0.000219826 0.000193152 0.000160521"/>
                      <joint name="right_elbow_roll_joint" pos="0 0 0" axis="1 0 0" range="-2.5569 2.5569" actuatorfrcrange="-24 24"/>
                      <geom class="visual" type="mesh" contype="0" conaffinity="0" group="1" density="0" rgba="1 1 1 1" mesh="right_elbow_roll_link"/>
                      <geom class="collision" type="mesh" rgba="1 1 1 1" mesh="right_elbow_roll_link"/>
                      <body name="right_wrist_pitch_link" pos="0.0803 0 0">
                        <inertial pos="-0.0001896 1e-05 0.0012297" quat="0.999571 0 -0.029273 0" mass="0.20778" diaginertia="6.48645e-05 6.46e-05 4.60355e-05"/>
                        <joint name="right_wrist_pitch_joint" pos="0 0 0" axis="0 1 0" range="-0.5585 0.5585" />
                        <geom class="visual" type="mesh" contype="0" conaffinity="0" group="1" density="0" rgba="0.2 0.2 0.2 1" mesh="right_wrist_pitch_link"/>
                        <!-- <geom class="collision" type="mesh" rgba="0.2 0.2 0.2 1" mesh="right_wrist_pitch_link"/> -->
                        <body name="right_wrist_yaw_link">
                          <inertial pos="-0.0197564 0 0.0299639" quat="0.969307 0 -0.245854 0" mass="0.017137" diaginertia="1.40313e-05 1.4e-05 3.76872e-06"/>
                          <joint name="right_wrist_yaw_joint" pos="0 0 0" axis="0 0 1" range="-1.5446 1.5446" actuatorfrcrange="-2.2 2.2"/>
                          <geom class="visual" quat="-0.706792 0 0.707421 0" type="mesh" contype="0" conaffinity="0" group="1" density="0" rgba="1 1 1 1" mesh="fright_wrist_yaw_link"/>
                          <geom class="collision" quat="-0.706704 0 0.707509 0" type="mesh" rgba="1 1 1 1" mesh="fright_wrist_yaw_link"/>
                        </body>
                      </body>
                    </body>
                  </body>
                </body>
              </body>
            </body>
          </body>
        </body>
      </body>
    </body>
  </worldbody>
  <actuator>
    <motor class="x2" name="motor_left_hip_pitch_joint" joint="left_hip_pitch_joint" ctrlrange="-118 118"/>
    <motor class="x2" name="motor_left_hip_roll_joint" joint="left_hip_roll_joint" ctrlrange="-118 118"/>
    <motor class="x2" name="motor_left_hip_yaw_joint" joint="left_hip_yaw_joint" ctrlrange="-118 118"/>
    <motor class="x2" name="motor_left_knee_joint" joint="left_knee_joint" ctrlrange="-118 118"/>
    <motor class="x2" name="motor_left_ankle_pitch_joint" joint="left_ankle_pitch_joint" ctrlrange="-36 36"/>
    <motor class="x2" name="motor_left_ankle_roll_joint" joint="left_ankle_roll_joint" ctrlrange="-24 24"/>

    <motor class="x2" name="motor_right_hip_pitch_joint" joint="right_hip_pitch_joint" ctrlrange="-118 118"/>
    <motor class="x2" name="motor_right_hip_roll_joint" joint="right_hip_roll_joint" ctrlrange="-118 118"/>
    <motor class="x2" name="motor_right_hip_yaw_joint" joint="right_hip_yaw_joint" ctrlrange="-118 118"/>
    <motor class="x2" name="motor_right_knee_joint" joint="right_knee_joint" ctrlrange="-118 118"/>
    <motor class="x2" name="motor_right_ankle_pitch_joint" joint="right_ankle_pitch_joint" ctrlrange="-36 36"/>
    <motor class="x2" name="motor_right_ankle_roll_joint" joint="right_ankle_roll_joint" ctrlrange="-24 24"/>

    <motor class="x2" name="motor_waist_yaw_joint" joint="waist_yaw_joint" ctrlrange="-118 118"/>
    <motor class="x2" name="motor_waist_pitch_joint" joint="waist_pitch_joint" ctrlrange="-48 48"/>
    <motor class="x2" name="motor_waist_roll_joint" joint="waist_roll_joint" ctrlrange="-48 48"/>

    <motor class="x2" name="motor_head_yaw_joint" joint="head_yaw_joint" ctrlrange="-2.6 2.6"/>
    <motor class="x2" name="motor_head_pitch_joint" joint="head_pitch_joint" ctrlrange="-0.6 0.6"/>

    <motor class="x2" name="motor_left_shoulder_pitch_joint" joint="left_shoulder_pitch_joint" ctrlrange="-36 36"/>
    <motor class="x2" name="motor_left_shoulder_roll_joint" joint="left_shoulder_roll_joint" ctrlrange="-36 36"/>
    <motor class="x2" name="motor_left_shoulder_yaw_joint" joint="left_shoulder_yaw_joint" ctrlrange="-24 24"/>
    <motor class="x2" name="motor_left_elbow_pitch_joint" joint="left_elbow_pitch_joint" ctrlrange="-24 24"/>
    <motor class="x2" name="motor_left_elbow_roll_joint" joint="left_elbow_roll_joint" ctrlrange="-24 24"/>
    <motor class="x2" name="motor_left_wrist_pitch_joint" joint="left_wrist_pitch_joint" ctrlrange="-2.2 2.2"/>
    <motor class="x2" name="motor_left_wrist_yaw_joint" joint="left_wrist_yaw_joint" ctrlrange="-2.2 2.2"/>

    <motor class="x2" name="motor_right_shoulder_pitch_joint" joint="right_shoulder_pitch_joint" ctrlrange="-36 36"/>
    <motor class="x2" name="motor_right_shoulder_roll_joint" joint="right_shoulder_roll_joint" ctrlrange="-36 36"/>
    <motor class="x2" name="motor_right_shoulder_yaw_joint" joint="right_shoulder_yaw_joint" ctrlrange="-24 24"/>
    <motor class="x2" name="motor_right_elbow_pitch_joint" joint="right_elbow_pitch_joint" ctrlrange="-24 24"/>
    <motor class="x2" name="motor_right_elbow_roll_joint" joint="right_elbow_roll_joint" ctrlrange="-24 24"/>
    <motor class="x2" name="motor_right_wrist_pitch_joint" joint="right_wrist_pitch_joint" ctrlrange="-2.2 2.2"/>
    <motor class="x2" name="motor_right_wrist_yaw_joint" joint="right_wrist_yaw_joint" ctrlrange="-2.2 2.2"/>
  </actuator>


  <sensor>
    <!-- <gyro name="imu0-gyro" site="imu_0" cutoff="7.85"/>
    <accelerometer name="imu0-acc" site="imu_0" cutoff="157"/>
    <framequat name="imu0-quat" objtype="site" objname="imu_0"/>

    <gyro name="imu1-gyro" site="imu_1" cutoff="7.85"/>
    <accelerometer name="imu1-acc" site="imu_1" cutoff="157"/>
    <framequat name="imu1-quat" objtype="site" objname="imu_1"/> -->

    <framequat name="body-orientation" objtype="site" objname="imu_0" noise="0"/>
    <gyro name="body-angular-velocity" site="imu_0" noise="0.001"/>
    <framepos name="body-linear-pos" objtype="site" objname="imu_0"/>
    <velocimeter name="body-linear-vel" site="imu_0"/>
    <accelerometer name="body-linear-acceleration" site="imu_0" noise="0.001"/>
    
    <jointpos name = 'jointpos_left_hip_pitch_joint' joint = 'left_hip_pitch_joint' noise = "0" />
    <jointpos name = 'jointpos_left_hip_roll_joint' joint = 'left_hip_roll_joint' noise = "0" />
    <jointpos name = 'jointpos_left_hip_yaw_joint' joint = 'left_hip_yaw_joint' noise = "0" />
    <jointpos name = 'jointpos_left_knee_joint' joint = 'left_knee_joint' noise = "0" />
    <jointpos name = 'jointpos_left_ankle_pitch_joint' joint = 'left_ankle_pitch_joint' noise = "0" />
    <jointpos name = 'jointpos_left_ankle_roll_joint' joint = 'left_ankle_roll_joint' noise = "0" />

    <jointpos name = 'jointpos_right_hip_pitch_joint' joint = 'right_hip_pitch_joint' noise = "0" />
    <jointpos name = 'jointpos_right_hip_roll_joint' joint = 'right_hip_roll_joint' noise = "0" />
    <jointpos name = 'jointpos_right_hip_yaw_joint' joint = 'right_hip_yaw_joint' noise = "0" />
    <jointpos name = 'jointpos_right_knee_joint' joint = 'right_knee_joint' noise = "0" />
    <jointpos name = 'jointpos_right_ankle_pitch_joint' joint = 'right_ankle_pitch_joint' noise = "0" />
    <jointpos name = 'jointpos_right_ankle_roll_joint' joint = 'right_ankle_roll_joint' noise = "0" />

    <jointpos name = 'jointpos_waist_yaw_joint' joint = 'waist_yaw_joint' noise = "0" />
    <jointpos name = 'jointpos_waist_pitch_joint' joint = 'waist_pitch_joint' noise = "0" />
    <jointpos name = 'jointpos_waist_roll_joint' joint = 'waist_roll_joint' noise = "0" />

    <jointpos name = 'jointpos_head_yaw_joint' joint = 'head_yaw_joint' noise = "0" />
    <jointpos name = 'jointpos_head_pitch_joint' joint = 'head_pitch_joint' noise = "0" />

    <jointpos name = 'jointpos_left_shoulder_pitch_joint' joint = 'left_shoulder_pitch_joint' noise = "0" />
    <jointpos name = 'jointpos_left_shoulder_roll_joint' joint = 'left_shoulder_roll_joint' noise = "0" />
    <jointpos name = 'jointpos_left_shoulder_yaw_joint' joint = 'left_shoulder_yaw_joint' noise = "0" />
    <jointpos name = 'jointpos_left_elbow_pitch_joint' joint = 'left_elbow_pitch_joint' noise = "0" />
    <jointpos name = 'jointpos_left_elbow_roll_joint' joint = 'left_elbow_roll_joint' noise = "0" />
    <jointpos name = 'jointpos_left_wrist_pitch_joint' joint = 'left_wrist_pitch_joint' noise = "0" />
    <jointpos name = 'jointpos_left_wrist_yaw_joint' joint = 'left_wrist_yaw_joint' noise = "0" />

    <jointpos name = 'jointpos_right_shoulder_pitch_joint' joint = 'right_shoulder_pitch_joint' noise = "0" />
    <jointpos name = 'jointpos_right_shoulder_roll_joint' joint = 'right_shoulder_roll_joint' noise = "0" />
    <jointpos name = 'jointpos_right_shoulder_yaw_joint' joint = 'right_shoulder_yaw_joint' noise = "0" />
    <jointpos name = 'jointpos_right_elbow_pitch_joint' joint = 'right_elbow_pitch_joint' noise = "0" />
    <jointpos name = 'jointpos_right_elbow_roll_joint' joint = 'right_elbow_roll_joint' noise = "0" />
    <jointpos name = 'jointpos_right_wrist_pitch_joint' joint = 'right_wrist_pitch_joint' noise = "0" />
    <jointpos name = 'jointpos_right_wrist_yaw_joint' joint = 'right_wrist_yaw_joint' noise = "0" />

    <jointvel name = 'jointvel_left_hip_pitch_joint' joint = 'left_hip_pitch_joint' noise = "0" />
    <jointvel name = 'jointvel_left_hip_roll_joint' joint = 'left_hip_roll_joint' noise = "0" />
    <jointvel name = 'jointvel_left_hip_yaw_joint' joint = 'left_hip_yaw_joint' noise = "0" />
    <jointvel name = 'jointvel_left_knee_joint' joint = 'left_knee_joint' noise = "0" />
    <jointvel name = 'jointvel_left_ankle_pitch_joint' joint = 'left_ankle_pitch_joint' noise = "0" />
    <jointvel name = 'jointvel_left_ankle_roll_joint' joint = 'left_ankle_roll_joint' noise = "0" />

    <jointvel name = 'jointvel_right_hip_pitch_joint' joint = 'right_hip_pitch_joint' noise = "0" />
    <jointvel name = 'jointvel_right_hip_roll_joint' joint = 'right_hip_roll_joint' noise = "0" />
    <jointvel name = 'jointvel_right_hip_yaw_joint' joint = 'right_hip_yaw_joint' noise = "0" />
    <jointvel name = 'jointvel_right_knee_joint' joint = 'right_knee_joint' noise = "0" />
    <jointvel name = 'jointvel_right_ankle_pitch_joint' joint = 'right_ankle_pitch_joint' noise = "0" />
    <jointvel name = 'jointvel_right_ankle_roll_joint' joint = 'right_ankle_roll_joint' noise = "0" />

    <jointvel name = 'jointvel_waist_yaw_joint' joint = 'waist_yaw_joint' noise = "0" />
    <jointvel name = 'jointvel_waist_pitch_joint' joint = 'waist_pitch_joint' noise = "0" />
    <jointvel name = 'jointvel_waist_roll_joint' joint = 'waist_roll_joint' noise = "0" />

    <jointvel name = 'jointvel_head_yaw_joint' joint = 'head_yaw_joint' noise = "0" />
    <jointvel name = 'jointvel_head_pitch_joint' joint = 'head_pitch_joint' noise = "0" />

    <jointvel name = 'jointvel_left_shoulder_pitch_joint' joint = 'left_shoulder_pitch_joint' noise = "0" />
    <jointvel name = 'jointvel_left_shoulder_roll_joint' joint = 'left_shoulder_roll_joint' noise = "0" />
    <jointvel name = 'jointvel_left_shoulder_yaw_joint' joint = 'left_shoulder_yaw_joint' noise = "0" />
    <jointvel name = 'jointvel_left_elbow_pitch_joint' joint = 'left_elbow_pitch_joint' noise = "0" />
    <jointvel name = 'jointvel_left_elbow_roll_joint' joint = 'left_elbow_roll_joint' noise = "0" />
    <jointvel name = 'jointvel_left_wrist_pitch_joint' joint = 'left_wrist_pitch_joint' noise = "0" />
    <jointvel name = 'jointvel_left_wrist_yaw_joint' joint = 'left_wrist_yaw_joint' noise = "0" />

    <jointvel name = 'jointvel_right_shoulder_pitch_joint' joint = 'right_shoulder_pitch_joint' noise = "0" />
    <jointvel name = 'jointvel_right_shoulder_roll_joint' joint = 'right_shoulder_roll_joint' noise = "0" />
    <jointvel name = 'jointvel_right_shoulder_yaw_joint' joint = 'right_shoulder_yaw_joint' noise = "0" />
    <jointvel name = 'jointvel_right_elbow_pitch_joint' joint = 'right_elbow_pitch_joint' noise = "0" />
    <jointvel name = 'jointvel_right_elbow_roll_joint' joint = 'right_elbow_roll_joint' noise = "0" />
    <jointvel name = 'jointvel_right_wrist_pitch_joint' joint = 'right_wrist_pitch_joint' noise = "0" />
    <jointvel name = 'jointvel_right_wrist_yaw_joint' joint = 'right_wrist_yaw_joint' noise = "0" />

  </sensor>
  <!-- <keyframe>
    <key name="stand" qpos="0 0 0.782 1 0 0 0 -0.21 0 0 0.45 -0.24 0 -0.21 0 0 0.45 -0.24 0 0 0 0 0 0 0 -0.81 0 0 0 0 0 0 -0.81 0 0 0 "/>
  </keyframe> -->
</mujoco>
