<mujoco model="x2t2">
  <compiler angle='radian' eulerseq="XYZ" meshdir="./meshes"
    autolimits="true" />

  <option timestep="0.001" />

  <!-- <visual>
    <global ellipsoidinertia="true"/>
  </visual> -->

  <default>
      <default class="x2">
          <site rgba="1 0 0 1" size="0.01" group="5"/>
          <joint damping="0.0" armature="0.03" frictionloss="0.3"/>
          <default class="visual">
              <geom group="2" type="mesh" contype="0" conaffinity="0" density="0" material="metallic"/>
          </default>
          <default class="collision">
              <geom group="3" type="mesh"/>
              <default class="foot">
                  <geom type="sphere" size="0.005"/>
              </default>
          </default>
      </default>

      <default class="finger_motor">
        <joint damping="0.01" armature="0.003" frictionloss="0.05"/>
        <site size="0.003" rgba="0 0 1 1"/>
      </default>

  </default>
  <asset>
    <material name="metallic" rgba="0.7 0.7 0.7 1"/>
    <material name="black_transparent" rgba="0.2 0.2 0.2 0.7"/>
    <material name="black" rgba="0.2 0.2 0.2 1"/>
    <material name="white" rgba="1 1 1 1"/>
    <material name="yellow" rgba="1 0.82 0.31 1"/>
    <material name="red" rgba="1 0 0 1"/>
    <mesh name="pelvis" file="pelvis.STL"/>
    <mesh name="imu_in_pelvis_link" file="imu_in_pelvis_link.STL"/>
    <mesh name="left_hip_pitch_link" file="left_hip_pitch_link.STL"/>
    <mesh name="left_hip_roll_link_collision" file="left_hip_roll_link.STL" scale="1.0 0.75 1.0"/>
    <mesh name="left_hip_roll_link" file="left_hip_roll_link.STL" scale="1.0 1.0 1.0"/>
    <mesh name="left_hip_yaw_link" file="left_hip_yaw_link.STL"/>
    <mesh name="left_knee_link" file="left_knee_link.STL"/>
    <mesh name="left_ankle_pitch_link" file="left_ankle_pitch_link.STL"/>
    <mesh name="left_ankle_roll_link" file="left_ankle_roll_link.STL"/>
    <mesh name="right_hip_pitch_link" file="right_hip_pitch_link.STL"/>
    <mesh name="right_hip_roll_link_collision" file="right_hip_roll_link.STL" scale="1.0 0.75 1.0"/>
    <mesh name="right_hip_roll_link" file="right_hip_roll_link.STL" scale="1.0 1.0 1.0"/>
    <mesh name="right_hip_yaw_link" file="right_hip_yaw_link.STL"/>
    <mesh name="right_knee_link" file="right_knee_link.STL"/>
    <mesh name="right_ankle_pitch_link" file="right_ankle_pitch_link.STL"/>
    <mesh name="right_ankle_roll_link" file="right_ankle_roll_link.STL"/>
    <mesh name="waist_yaw_link" file="waist_yaw_link.STL"/>
    <mesh name="waist_pitch_link" file="waist_pitch_link.STL"/>
    <mesh name="torso_link" file="torso_link.STL"/>
    <mesh name="imu_in_turso_link" file="imu_in_turso_link.STL"/>
    <mesh name="left_shoulder_pitch_link" file="left_shoulder_pitch_link.STL"/>
    <mesh name="left_shoulder_roll_link" file="left_shoulder_roll_link.STL"/>
    <mesh name="left_shoulder_yaw_link" file="left_shoulder_yaw_link.STL"/>
    <mesh name="left_elbow_link" file="left_elbow_link.STL"/>
    <mesh name="left_wrist_yaw_link" file="left_wrist_yaw_link.STL"/>
    <mesh name="left_wrist_pitch_link" file="left_wrist_pitch_link.STL"/>
    <mesh name="left_wrist_roll_link" file="left_wrist_roll_link.STL"/>
    <mesh name="left_wrist_roll_yellow_link" content_type="model/stl" file="left_wrist_roll_yellow_link.STL"/>
    <mesh name="left_wrist_roll_extend_link" file="left_wrist_roll_extend_link.STL" scale="1.01 1.01 1.01"/>
    <mesh name="left_wrist_roll_extend_link1" file="left_wrist_roll_extend_link.STL" scale="0.99 0.99 0.99"/>
    <mesh name="right_shoulder_pitch_link" file="right_shoulder_pitch_link.STL"/>
    <mesh name="right_shoulder_roll_link" file="right_shoulder_roll_link.STL"/>
    <mesh name="right_shoulder_yaw_link" file="right_shoulder_yaw_link.STL"/>
    <mesh name="right_elbow_link" file="right_elbow_link.STL"/>
    <mesh name="right_wrist_yaw_link" file="right_wrist_yaw_link.STL"/>
    <mesh name="right_wrist_pitch_link" file="right_wrist_pitch_link.STL"/>
    <mesh name="right_wrist_roll_link" file="right_wrist_roll_link.STL"/>
    <mesh name="right_wrist_roll_yellow_link" content_type="model/stl" file="right_wrist_roll_yellow_link.STL"/>
    <mesh name="right_wrist_roll_extend_link" file="right_wrist_roll_extend_link.STL" scale="1.01 1.01 1.01"/>
    <mesh name="right_wrist_roll_extend_link1" file="right_wrist_roll_extend_link.STL" scale="0.99 0.99 0.99"/>
    <mesh name="head_yaw_link" file="head_yaw_link.STL"/>
    <mesh name="head_pitch_link" file="head_pitch_link.STL"/>
    <mesh name="imu_in_head_link" file="imu_in_head_link.STL"/>
    <mesh name="RGBD_in_head_link" file="RGBD_in_head_link.STL"/>
    <mesh name="RGB_REAR_link" file="RGB_REAR_link.STL"/>
    <mesh name="lidar_link" file="lidar_link.STL"/>
    <mesh name="l_palm"  file="l_palm.STL"/>
    <mesh name="l_thumb_roll" file="l_thumb_roll.STL"/>
    <mesh name="thumb_abad" file="thumb_abad.STL"/>
    <mesh name="thumb_mcp" file="thumb_mcp.STL"/>
    <mesh name="thumb_pip" file="thumb_pip.STL"/>
    <mesh name="thumb_dip" file="thumb_dip.STL"/>
    <mesh name="finger_abad" file="finger_abad.STL"/>
    <mesh name="finger_pip" file="finger_pip.STL"/>
    <mesh name="finger_dip" file="finger_dip.STL"/>
    <mesh name="r_palm"  file="r_palm.STL"/>
    <mesh name="r_thumb_roll" file="r_thumb_roll.STL"/>
  </asset>

  <!-- 新增手指随动关节约束关系 -->
  <equality>
    <joint joint1="L_thumb_pip_joint" joint2="L_thumb_mcp_joint" polycoef="0 1.33 0 0 0"/>
    <joint joint1="L_thumb_dip_joint" joint2="L_thumb_mcp_joint" polycoef="0 1.3 0 0 0"/>
    <joint joint1="L_index_dip_joint" joint2="L_index_pip_joint" polycoef="0 1.097 0 0 0"/>
    <joint joint1="L_middle_dip_joint" joint2="L_middle_pip_joint" polycoef="0 1.097 0 0 0"/>
    <joint joint1="L_ring_dip_joint" joint2="L_ring_pip_joint" polycoef="0 1.097 0 0 0"/>
    <joint joint1="L_pinky_dip_joint" joint2="L_pinky_pip_joint" polycoef="0 1.097 0 0 0"/>

    <joint joint1="R_thumb_pip_joint" joint2="R_thumb_mcp_joint" polycoef="0 1.33 0 0 0"/>
    <joint joint1="R_thumb_dip_joint" joint2="R_thumb_mcp_joint" polycoef="0 1.3 0 0 0"/>
    <joint joint1="R_index_dip_joint" joint2="R_index_pip_joint" polycoef="0 1.097 0 0 0"/>
    <joint joint1="R_middle_dip_joint" joint2="R_middle_pip_joint" polycoef="0 1.097 0 0 0"/>
    <joint joint1="R_ring_dip_joint" joint2="R_ring_pip_joint" polycoef="0 1.097 0 0 0"/>
    <joint joint1="R_pinky_dip_joint" joint2="R_pinky_pip_joint" polycoef="0 1.097 0 0 0"/>
  </equality>
   <!-- 新增手指随动关节约束关系 -->

  <worldbody>
    <body name="pelvis" pos="0 0 0.8" euler="0 0 0" childclass="x2">
      <light name="tracking" mode="trackcom" pos="0 0 2"/>
      <freejoint name="floating_base_joint"/>
      <geom class="visual" type="mesh" contype="0" conaffinity="0" group="1" density="0" rgba="0.2 0.2 0.2 1" mesh="pelvis"/>
      <geom class="collision" group="2" type="mesh" rgba="0.2 0.2 0.2 1" mesh="pelvis"/>
      <geom class="visual" group="3" pos="0.0238693 0.00184435 0.03986" quat="1 0 0 0" type="mesh" contype="0" conaffinity="0" density="0" mesh="imu_in_pelvis_link"/>
      <site name="imu_0" pos="0.0238693 0.00184435 0.03986" group="3"/>
      <body name="left_hip_pitch_link" pos="0 0.07135 0">
        <inertial pos="0.0093 -0.0648 0.0004" mass="1.38536" diaginertia="0.0015 0.0011 0.0011"/>
        <joint name="left_hip_pitch_joint" pos="0 0 0" axis="0 1 0" range="-2.556 2.556" actuatorfrcrange="-120 120"/>
        <geom class="visual" type="mesh" contype="0" conaffinity="0" group="1" density="0" rgba="0.2 0.2 0.2 1" mesh="left_hip_pitch_link"/>
        <!-- <geom class="collision" group="2" type="mesh" rgba="0.2 0.2 0.2 1" mesh="left_hip_pitch_link"/> -->
        <body name="left_hip_roll_link" pos="0.03585 0.0657007 0">
          <inertial pos="-0.0352309 0.0003382 -0.0981039" quat="0.70862 -0.00853395 -0.0149656 0.70538" mass="1.52075" diaginertia="0.00335774 0.00294264 0.00181162"/>
          <joint name="left_hip_roll_joint" pos="0 0 0" axis="1 0 0" range="-0.235 2.967" actuatorfrcrange="-120 120"/>
          <geom class="visual" type="mesh" contype="0" conaffinity="0" group="1" density="0" rgba="1 1 1 1" mesh="left_hip_roll_link"/>
          <geom class="collision" group="2" type="mesh" rgba="1 1 1 1" mesh="left_hip_roll_link_collision"/>
          <body name="left_hip_yaw_link" pos="-0.0358507 0 -0.136851">
            <inertial pos="-0.0025555 0.0055953 -0.146313" quat="0.652335 -0.0502682 -0.0150617 0.756112" mass="1.95146" diaginertia="0.00980555 0.00932298 0.00226827"/>
            <joint name="left_hip_yaw_joint" pos="0 0 0" axis="0 0 1" range="-1.685 3.43" actuatorfrcrange="-120 120"/>
            <geom class="visual" type="mesh" contype="0" conaffinity="0" group="1" density="0" rgba="1 1 1 1" mesh="left_hip_yaw_link"/>
            <geom class="collision" group="2" type="mesh" rgba="1 1 1 1" mesh="left_hip_yaw_link"/>
            <body name="left_knee_link" pos="-0.00765858 0.000174187 -0.183101">
              <inertial pos="-0.0010229 0.0040912 -0.129669" quat="0.547995 0.0282228 0.00643982 0.835981" mass="1.7853" diaginertia="0.00946279 0.00936609 0.00263801"/>
              <joint name="left_knee_joint" pos="0 0 0" axis="0 1 0" range="0 2.12" actuatorfrcrange="-120 120"/>
              <geom class="visual" type="mesh" contype="0" conaffinity="0" group="1" density="0" rgba="1 1 1 1" mesh="left_knee_link"/>
              <geom class="collision" group="2" type="mesh" rgba="1 1 1 1" mesh="left_knee_link"/>
              <body name="left_ankle_pitch_link" pos="-0.0100007 -0.000175 -0.281999">
                <inertial pos="-0.0007844 4.82e-05 -3.38e-05" quat="0.45785 0.541086 0.452886 0.540827" mass="0.606354" diaginertia="0.000420939 0.000419769 0.000278093"/>
                <joint name="left_ankle_pitch_joint" pos="0 0 0" axis="0 1 0" range="-0.803 0.453" actuatorfrcrange="-36 36"/>
                <geom class="visual" type="mesh" contype="0" conaffinity="0" group="1" density="0" rgba="0.2 0.2 0.2 1" mesh="left_ankle_pitch_link"/>
                <!-- <geom class="collision" group="2" type="mesh" rgba="0.2 0.2 0.2 1" mesh="left_ankle_pitch_link"/> -->
                <body name="left_ankle_roll_link" pos="-0.00055 0 0">
                  <inertial pos="0.0339194 3.43e-05 -0.0522239" quat="0.00133871 0.713547 0.00112807 0.700606" mass="0.971794" diaginertia="0.00437369 0.00376659 0.00115472"/>
                  <joint name="left_ankle_roll_joint" pos="0 0 0" axis="1 0 0" range="-0.262 0.262" actuatorfrcrange="-24 24"/>
                  <geom class="visual" type="mesh" contype="0" conaffinity="0" group="1" density="0" rgba="1 0.5 0 1" mesh="left_ankle_roll_link"/>
                  <geom class="collision" type="sphere" group="2"  size="0.005" pos="-0.05 0.05 -0.068" rgba="1 0.5 0 1"/>
                  <geom class="collision" type="sphere" group="2"  size="0.005" pos="-0.065 0.025 -0.068" rgba="1 0.5 0 1"/>
                  <geom class="collision" type="sphere" group="2"  size="0.005" pos="-0.05 -0.05 -0.068" rgba="1 0.5 0 1"/>
                  <geom class="collision" type="sphere" group="2"  size="0.005" pos="-0.065 -0.025 -0.068" rgba="1 0.5 0 1"/>
                  <geom class="collision" type="sphere" group="2"  size="0.005" pos="0.11 0.05 -0.068" rgba="1 0.5 0 1"/>

                  <geom class="collision" type="sphere" group="2"  size="0.005" pos="0.11 -0.05 -0.068" rgba="1 0.5 0 1"/>
                  <geom class="collision" type="sphere" group="2"  size="0.005" pos="-0.02 -0.06 -0.068" rgba="1 0.5 0 1"/>
                  <geom class="collision" type="sphere" group="2"  size="0.005" pos="-0.02 0.06 -0.068" rgba="1 0.5 0 1"/>
                  <geom class="collision" type="sphere" group="2"  size="0.005" pos="0.07 -0.06 -0.068" rgba="1 0.5 0 1"/>
                  <geom class="collision" type="sphere" group="2"  size="0.005" pos="0.07 0.06 -0.068" rgba="1 0.5 0 1"/>
                  <geom class="collision" type="sphere" group="2"  size="0.005" pos="0.139 0 -0.066" rgba="1 0.5 0 1"/>
                  <geom class="collision" type="sphere" group="2"  size="0.005" pos="0.128 0 -0.02" rgba="1 0.5 0 1"/>
                </body>
              </body>
            </body>
          </body>
        </body>
      </body>
      <body name="right_hip_pitch_link" pos="0 -0.07135 0">
        <inertial pos="0.0140094 -0.0737821 -0.0018104" quat="0.767644 0.64066 -0.00728044 -0.0150172" mass="1.38536" diaginertia="0.00147432 0.00114897 0.00108981"/>
        <joint name="right_hip_pitch_joint" pos="0 0 0" axis="0 1 0" range="-2.556 2.556" actuatorfrcrange="-120 120"/>
        <geom class="visual" type="mesh" contype="0" conaffinity="0" group="1" density="0" rgba="0.2 0.2 0.2 1" mesh="right_hip_pitch_link"/>
        <!-- <geom class="collision" group="2" type="mesh" rgba="0.2 0.2 0.2 1" mesh="right_hip_pitch_link"/> -->
        <body name="right_hip_roll_link" pos="0.0358508 -0.0656702 0.000185814">
          <inertial pos="-0.0356964 0.0002895 -0.0981308" quat="0.706834 -0.00282825 -0.00149793 0.707372" mass="1.52075" diaginertia="0.00335131 0.00293664 0.00180895"/>
          <joint name="right_hip_roll_joint" pos="0 0 0" axis="1 0 0" range="-2.906 0.235" actuatorfrcrange="-120 120"/>
          <geom class="visual" type="mesh" contype="0" conaffinity="0" group="1" density="0" rgba="1 1 1 1" mesh="right_hip_roll_link"/>
          <geom class="collision" group="2" type="mesh" rgba="1 1 1 1" mesh="right_hip_roll_link_collision"/>
          <body name="right_hip_yaw_link" pos="-0.0358507 0.000389336 -0.136849" quat="0.999999 0.00141953 0 0">
            <inertial pos="-0.0032925 -0.0027487 -0.137288" quat="0.777382 -0.00391413 -0.04867 0.627131" mass="1.95145" diaginertia="0.00976282 0.00930166 0.00224152"/>
            <joint name="right_hip_yaw_joint" pos="0 0 0" axis="0 0 1" range="-3.43 1.685" actuatorfrcrange="-120 120"/>
            <geom class="visual" type="mesh" contype="0" conaffinity="0" group="1" density="0" rgba="1 1 1 1" mesh="right_hip_yaw_link"/>
            <geom class="collision" group="2" type="mesh" rgba="1 1 1 1" mesh="right_hip_yaw_link"/>
            <body name="right_knee_link" pos="-0.00766 -0.000154353 -0.183115">
              <inertial pos="-0.0020116 -0.0023774 -0.129801" quat="0.912886 -0.00189951 0.0297526 0.407125" mass="1.78533" diaginertia="0.00948983 0.00935633 0.00261524"/>
              <joint name="right_knee_joint" pos="0 0 0" axis="0 1 0" range="0 2.12" actuatorfrcrange="-120 120"/>
              <geom class="visual" type="mesh" contype="0" conaffinity="0" group="1" density="0" rgba="1 1 1 1" mesh="right_knee_link"/>
              <geom class="collision" group="2" type="mesh" rgba="1 1 1 1" mesh="right_knee_link"/>
              <body name="right_ankle_pitch_link" pos="-0.00999928 0.000175 -0.281985">
                <inertial pos="-0.0007844 8.08e-05 -4.17e-05" quat="0.4645 0.535445 0.45954 0.535128" mass="0.606354" diaginertia="0.000421034 0.000419674 0.000278093"/>
                <joint name="right_ankle_pitch_joint" pos="0 0 0" axis="0 1 0" range="-0.803 0.453" actuatorfrcrange="-36 36"/>
                <geom class="visual" type="mesh" contype="0" conaffinity="0" group="1" density="0" rgba="0.2 0.2 0.2 1" mesh="right_ankle_pitch_link"/>
                <!-- <geom class="collision" group="2" type="mesh" rgba="0.2 0.2 0.2 1" mesh="right_ankle_pitch_link"/> -->
                <body name="right_ankle_roll_link" pos="-0.00045 0 0">
                  <inertial pos="0.0338194 -4.28e-05 -0.0522239" quat="-0.0011166 0.713547 -0.00142142 0.700605" mass="0.971794" diaginertia="0.00437369 0.00376659 0.00115472"/>
                  <joint name="right_ankle_roll_joint" pos="0 0 0" axis="1 0 0" range="-0.262 0.262" actuatorfrcrange="-24 24"/>
                  <geom class="visual" type="mesh" contype="0" conaffinity="0" group="1" density="0" rgba="1 0.5 0 1" mesh="right_ankle_roll_link"/>
                  <geom class="collision" type="sphere" group="2" size="0.005" pos="-0.05 0.05 -0.068" rgba="1 0.5 0 1"/>
                  <geom class="collision" type="sphere" group="2" size="0.005" pos="-0.065 0.025 -0.068" rgba="1 0.5 0 1"/>
                  <geom class="collision" type="sphere" group="2" size="0.005" pos="-0.05 -0.05 -0.068" rgba="1 0.5 0 1"/>
                  <geom class="collision" type="sphere" group="2" size="0.005" pos="-0.065 -0.025 -0.068" rgba="1 0.5 0 1"/>
                  <geom class="collision" type="sphere" group="2" size="0.005" pos="0.11 0.05 -0.068" rgba="1 0.5 0 1"/>
                  <geom class="collision" type="sphere" group="2" size="0.005" pos="0.11 -0.05 -0.068" rgba="1 0.5 0 1"/>
                  <geom class="collision" type="sphere" group="2" size="0.005" pos="-0.02 -0.06 -0.068" rgba="1 0.5 0 1"/>
                  <geom class="collision" type="sphere" group="2" size="0.005" pos="-0.02 0.06 -0.068" rgba="1 0.5 0 1"/>
                  <geom class="collision" type="sphere" group="2" size="0.005" pos="0.07 -0.06 -0.068" rgba="1 0.5 0 1"/>
                  <geom class="collision" type="sphere" group="2" size="0.005" pos="0.07 0.06 -0.068" rgba="1 0.5 0 1"/>
                  <geom class="collision" type="sphere" group="2" size="0.005" pos="0.139 0 -0.066" rgba="1 0.5 0 1"/>
                  <geom class="collision" type="sphere" group="2" size="0.005" pos="0.128 0 -0.02" rgba="1 0.5 0 1"/>
                </body>
              </body>
            </body>
          </body>
        </body>
      </body>
      <body name="waist_yaw_link" pos="0 0 0.06705">
        <inertial pos="-0.0015024 -3.11e-05 0.0285932" quat="0.938724 0.00909683 0.344548 -0.000708464" mass="1.65939" diaginertia="0.00209166 0.00184931 0.00180643"/>
        <joint name="waist_yaw_joint" pos="0 0 0" axis="0 0 1" range="-3.43 2.382" actuatorfrcrange="-120 120"/>
        <geom class="visual" type="mesh" contype="0" conaffinity="0" group="1" density="0" rgba="0.2 0.2 0.2 1" mesh="waist_yaw_link"/>
        <!-- <geom class="collision" group="2" type="mesh" rgba="0.2 0.2 0.2 1" mesh="waist_yaw_link"/> -->
        <body name="waist_pitch_link" pos="0 0 0.0883">
          <inertial pos="-0.0004704 0 0" quat="0.707107 0.707107 0 0" mass="0.219156" diaginertia="9.75e-05 9.64e-05 2.22e-05"/>
          <joint name="waist_pitch_joint" pos="0 0 0" axis="0 1 0" range="-0.314 0.314" actuatorfrcrange="-48 48"/>
          <geom class="visual" type="mesh" contype="0" conaffinity="0" group="1" density="0" rgba="0.2 0.2 0.2 1" mesh="waist_pitch_link"/>
          <!-- <geom class="collision" group="2" type="mesh" rgba="0.2 0.2 0.2 1" mesh="waist_pitch_link"/> -->
          <body name="torso_link">
            <inertial pos="-0.0124573 0.0010231 0.18347" quat="0.99788 0.00805319 0.0645573 0.00184711" mass="9.54094" diaginertia="0.103443 0.0789803 0.0571975"/>
            <joint name="waist_roll_joint" pos="0 0 0" axis="1 0 0" range="-0.488 0.488" actuatorfrcrange="-48 48"/>
            <geom class="visual" type="mesh" contype="0" conaffinity="0" group="1" density="0" rgba="1 1 1 1" mesh="torso_link"/>
            <geom class="collision" group="2" type="mesh" rgba="1 1 1 1" mesh="torso_link"/>
            <site name="imu_1" pos="-0.0248812 0.00194383 0.10569" group="3"/>
            <geom class="visual" group="3" pos="-0.0248812 0.00194383 0.10569" quat="1 0 0 0" type="mesh" contype="0" conaffinity="0"  density="0" mesh="imu_in_turso_link"/>

            <body name="left_shoulder_pitch_link" pos="0.00299998 0.142735 0.241589" quat="0.994522 0.104528 0 0">
              <inertial pos="0.0063224 0.0511625 0.0001873" quat="0.690102 0.720921 0.0559555 0.0300097" mass="0.833496" diaginertia="0.000494586 0.000442103 0.000411611"/>
              <joint name="left_shoulder_pitch_joint" pos="0 0 0" axis="0 1 0" range="-2.556 2.556" actuatorfrcrange="-36 36"/>
              <geom class="visual" type="mesh" contype="0" conaffinity="0" group="1" density="0" rgba="0.2 0.2 0.2 1" mesh="left_shoulder_pitch_link"/>
              <!-- <geom class="collision" group="2" type="mesh" rgba="0.2 0.2 0.2 1" mesh="left_shoulder_pitch_link"/> -->
              <body name="left_shoulder_roll_link" pos="0.027 0.0495 0">
                <inertial pos="-0.030939 -0.0001616 -0.0847913" quat="0.704453 0.00987646 0.0025035 0.709678" mass="0.6614" diaginertia="0.00101516 0.000947851 0.000446484"/>
                <joint name="left_shoulder_roll_joint" pos="0 0 0" axis="1 0 0" range="-0.061 2.993" actuatorfrcrange="-36 36"/>
                <geom class="visual" type="mesh" contype="0" conaffinity="0" group="1" density="0" rgba="1 1 1 1" mesh="left_shoulder_roll_link"/>
                <geom class="collision" group="2" type="mesh" rgba="1 1 1 1" mesh="left_shoulder_roll_link"/>
                <body name="left_shoulder_yaw_link" pos="-0.027 0 -0.1212">
                  <inertial pos="0.0100788 0.0053363 -0.0735865" quat="0.895223 0.0115094 0.124674 0.427667" mass="0.6722" diaginertia="0.000732479 0.000687627 0.000373894"/>
                  <joint name="left_shoulder_yaw_joint" pos="0 0 0" axis="0 0 1" range="-2.556 2.556" actuatorfrcrange="-24 24"/>
                  <geom class="visual" type="mesh" contype="0" conaffinity="0" group="1" density="0" rgba="1 1 1 1" mesh="left_shoulder_yaw_link"/>
                  <geom class="collision" group="2" type="mesh" rgba="1 1 1 1" mesh="left_shoulder_yaw_link"/>
                  <body name="left_elbow_link" pos="0.014 0.000199986 -0.083">
                    <inertial pos="-0.0142202 0.002941 -0.0861272" quat="0.965072 0.129601 -0.0314407 0.225502" mass="0.655564" diaginertia="0.000795062 0.000759662 0.000332876"/>
                    <joint name="left_elbow_joint" pos="0 0 0" axis="0 1 0" range="-2.556 0" actuatorfrcrange="-24 24"/>
                    <geom class="visual" type="mesh" contype="0" conaffinity="0" group="1" density="0" rgba="1 1 1 1" mesh="left_elbow_link"/>
                    <geom class="collision" group="2" type="mesh" rgba="1 1 1 1" mesh="left_elbow_link"/>
                    <body name="left_wrist_yaw_link" pos="-0.014 -0.000197548 -0.120694">
                      <inertial pos="0.0003175 0.0026769 -0.0321983" quat="0.984763 0.171421 0.0109846 0.027125" mass="0.322834" diaginertia="0.000255993 0.000210604 0.000171403"/>
                      <joint name="left_wrist_yaw_joint" pos="0 0 0" axis="0 0 1" range="-2.556 2.556" actuatorfrcrange="-24 24" ref="1.57"/>
                      <geom class="visual" type="mesh" contype="0" conaffinity="0" group="1" density="0" rgba="1 1 1 1" mesh="left_wrist_yaw_link"/>
                      <geom class="collision" group="2" type="mesh" rgba="1 1 1 1" mesh="left_wrist_yaw_link"/>
                      <body name="left_wrist_pitch_link" pos="0 0 -0.0803">
                        <inertial pos="-0.0005238 -1.48e-05 0.0002818" quat="0 0.752259 0 0.658868" mass="0.2189" diaginertia="6.44393e-05 6.38e-05 5.06607e-05"/>
                        <joint name="left_wrist_pitch_joint" pos="0 0 0" axis="0 1 0" range="-0.558 0.558" actuatorfrcrange="-4.8 4.8"/>
                        <geom class="visual" type="mesh" contype="0" conaffinity="0" group="1" density="0" rgba="0.2 0.2 0.2 1" mesh="left_wrist_pitch_link"/>
                        <!-- <geom class="collision" group="2" type="mesh" rgba="0.2 0.2 0.2 1" mesh="left_wrist_pitch_link"/> -->
                        <body name="left_wrist_roll_link" pos="0.00085 0 0">
                          <inertial pos="0.0036751 0.0015642 -0.0906068" quat="0.795067 -0.00736773 0.00761083 0.60643" mass="0.258845" diaginertia="0.000573327 0.000481054 0.000169319"/>
                          <joint name="left_wrist_roll_joint" pos="0 0 0" axis="1 0 0" range="-1.544 1.554" actuatorfrcrange="-4.8 4.8"/>
                          <geom  class="visual" type="mesh" contype="0" conaffinity="0" group="1" density="0" rgba="0.2 0.2 0.2 1" mesh="left_wrist_roll_extend_link"/>
                          <geom  class="visual" type="mesh" contype="0" conaffinity="0" group="1" density="0" rgba="0.2 0.2 0.2 1" mesh="left_wrist_roll_extend_link1"/>
                          <!-- <geom  class="collision" group="2" type="mesh" rgba="0.2 0.2 0.2 1" mesh="right_wrist_roll_yellow_link"/> -->
                          <geom class="visual" pos="0 0 -0.046" quat="0.000796327 0.999999683 0.0 0.0" type="mesh" contype="0" conaffinity="0" group="1" density="0" mesh="l_palm"/>
                          <!-- 手掌碰撞体：暂时禁用，避免影响平衡 -->
                          <!-- <geom size="0.015 0.03 0.03" pos="0 -9.07812e-05 -0.103" quat="0.000796327 0.999999683 0.0 0.0" type="box" group="3" rgba="1 0.5 0 0.3"/> -->
                          <geom pos="-0.0025 0.00779622 -0.142561" quat="0.000796327 0.999999683 0.0 0.0" type="mesh" contype="0" conaffinity="0" group="1" density="0" mesh="finger_abad"/>
                          <body name="L_thumb_roll" pos="0 0.0184452 -0.0935804" quat="0.000796327 0.999999683 0.0 0.0">
                            <inertial pos="-0.003851 0.000311 0.008401" quat="0.501033 0.516685 -0.497903 0.483834" mass="0.025" diaginertia="3.69257e-06 2.85892e-06 2.00851e-06"/>
                            <joint name="L_thumb_roll_joint" pos="0 0 0" axis="1 0 0" range="-0.872665 0.174533" actuatorfrcrange="-2.0 2.0"/>
                            <geom class="visual" type="mesh" contype="0" conaffinity="0" group="1" density="0" mesh="l_thumb_roll"/>
                            <body name="L_thumb_abad" pos="0.020801 -0.004292 -0.00052506">
                              <inertial pos="-1.2e-06 -0.0129928 -0.0041829" quat="0.996767 0.0803509 0 0" mass="0.0056" diaginertia="1.03e-06 8.89737e-07 5.10263e-07"/>
                              <joint name="L_thumb_abad_joint" pos="0 0 0" axis="0 0 1" range="0 1.74533" actuatorfrcrange="-2.0 2.0"/>
                              <geom class="visual" quat="0.000796327 0 0 1" type="mesh" contype="0" conaffinity="0" group="1" density="0" mesh="thumb_abad"/>
                              <body name="L_thumb_mcp" pos="0 -0.0265 -0.005275">
                                <inertial pos="-1.83e-05 -0.0225829 0.0024013" quat="0.722157 0.691728 0.000351102 0.000532546" mass="0.0511" diaginertia="1.274e-05 1.12221e-05 4.70793e-06"/>
                                <joint name="L_thumb_mcp_joint" pos="0 0 0" axis="1 0 0" range="-0.855211 0" actuatorfrcrange="-2.0 2.0"/>
                                <geom class="visual" quat="0.000796327 0 0 1" type="mesh" contype="0" conaffinity="0" group="1" density="0" mesh="thumb_mcp"/>
                                <!--<geom class="collision" size="0.0145 0.021 0.01625" pos="0 -0.0065 0.00237" type="box"/>-->
                                <body name="L_thumb_pip" pos="0 -0.036231 0.0036755">
                                  <inertial pos="-1e-06 -0.014461 -0.00415" quat="0.659121 0.752037 0 0" mass="0.011" diaginertia="1.34e-06 1.31926e-06 7.80742e-07"/>
                                  <joint name="L_thumb_pip_joint" pos="0 0 0" axis="1 0 0" range="-1.13446 0" actuatorfrcrange="-2.0 2.0"/>
                                  <geom class="visual" quat="0.000796327 0 0 1" type="mesh" contype="0" conaffinity="0" group="1" density="0" rgba="1 1 1 1" mesh="thumb_pip"/>
                                  <!-- <geom size="0.0095 0.0175 0.01125" pos="0 -0.0116 -0.0032" quat="0.995004 0.0998334 0 0" type="box" rgba="1 1 1 1"/> -->
                                  <body name="L_thumb_dip" pos="0 -0.026468 -0.0073106">
                                    <inertial pos="-3e-06 -0.010392 -0.001614" quat="0.628672 0.323685 -0.323685 0.628672" mass="0.007" diaginertia="5.54189e-07 5.2e-07 2.15811e-07"/>
                                    <joint name="L_thumb_dip_joint" pos="0 0 0" axis="1 0 0" range="-1.13446 0" actuatorfrcrange="-2.0 2.0"/>
                                    <geom class="visual" quat="0.000796327 0 0 1" type="mesh" contype="0" conaffinity="0" group="1" density="0" rgba="1 1 1 1" mesh="thumb_dip"/>
                                    <geom size="0.001" pos="0 -0.02392 -0.01158" contype="0" conaffinity="0" group="1" density="0" rgba="1 1 1 1"/>
                                    <!-- 指尖碰撞体：暂时禁用，测试是否影响重心 -->
                                    <!-- <geom type="sphere" size="0.0015" pos="0 -0.02392 -0.01158" group="2" friction="0.05 0.001 0.0001" rgba="1 0.5 0 0.2"/> -->
                                  </body>
                                </body>
                              </body>
                            </body>
                          </body>
                          <body name="L_index_abad" pos="0 0.0267994 -0.140591" quat="0.000796327 0.999999683 0.0 0.0">
                            <inertial pos="-0.0018959 -9.8e-06 0.0066855" quat="0.707029 0.0104741 0.0104741 0.707029" mass="0.04" diaginertia="8.82e-06 7.37415e-06 2.64585e-06"/>
                            <joint name="L_index_abad_joint" pos="0 0 0" axis="1 0 0" range="0 0.20944" actuatorfrcrange="-2.0 2.0"/>
                            <geom type="mesh" contype="0" conaffinity="0" group="1" density="0" mesh="finger_abad"/>
                            <body name="L_index_pip" pos="0.00048163 0 0.017575">
                              <inertial pos="-0.002884 1.5e-06 0.019997" quat="0.999936 0 -0.0113556 0" mass="0.004" diaginertia="7.00227e-07 6.8e-07 2.59773e-07"/>
                              <joint name="L_index_pip_joint" pos="0 0 0" axis="0 1 0" range="0 1.5708" actuatorfrcrange="-2.0 2.0"/>
                              <geom type="mesh" contype="0" conaffinity="0" group="1" density="0" mesh="finger_pip"/>
                              <!-- 指节碰撞体：移除，避免影响爬起（只保留指尖碰撞体） -->
                              <!-- <geom type="sphere" size="0.003" pos="0.00048163 0 0.017575" group="2" friction="0.1 0.005 0.0001" rgba="1 0.5 0 0.2"/> -->
                              <body name="L_index_dip" pos="-0.0015 0 0.036">
                                <inertial pos="0.000618 0 0.019239" mass="0.003" diaginertia="4e-07 4e-07 1.2e-07"/>
                                <joint name="L_index_dip_joint" pos="0 0 0" axis="0 1 0" range="0 1.8326" actuatorfrcrange="-2.0 2.0"/>
                                <geom type="mesh" contype="0" conaffinity="0" group="1" density="0" mesh="finger_dip"/>
                                <geom size="0.001" pos="-0.0011 0 0.03612" contype="0" conaffinity="0" group="1" density="0" rgba="1 1 1 1"/>
                                <!-- 指尖碰撞体：暂时禁用，测试是否影响重心 -->
                                <!-- <geom type="sphere" size="0.0015" pos="-0.0011 0 0.03612" group="2" friction="0.05 0.001 0.0001" rgba="1 0.5 0 0.2"/> -->
                              </body>
                            </body>
                          </body>
                          <body name="L_middle_pip" pos="-0.00201837 0.00776823 -0.160136" quat="0.000796327 0.999999683 0.0 0.0">
                            <inertial pos="-0.002884 1.5e-06 0.019997" quat="0.999936 0 -0.0113556 0" mass="0.004" diaginertia="7.00227e-07 6.8e-07 2.59773e-07"/>
                            <joint name="L_middle_pip_joint" pos="0 0 0" axis="0 1 0" range="0 1.5708" actuatorfrcrange="-2.0 2.0"/>
                            <geom type="mesh" contype="0" conaffinity="0" group="1" density="0" mesh="finger_pip"/>
                            <!-- 指节碰撞体：移除，避免影响爬起（只保留指尖碰撞体） -->
                            <!-- <geom type="sphere" size="0.003" pos="-0.00201837 0.00776823 -0.160136" quat="0.000796327 0.999999683 0.0 0.0" group="2" friction="0.1 0.005 0.0001" rgba="1 0.5 0 0.2"/> -->
                            <body name="L_middle_dip" pos="-0.0015 0 0.036">
                              <inertial pos="0.000618 0 0.019239" mass="0.003" diaginertia="4e-07 4e-07 1.2e-07"/>
                              <joint name="L_middle_dip_joint" pos="0 0 0" axis="0 1 0" range="0 1.8326" actuatorfrcrange="-2.0 2.0"/>
                              <geom type="mesh" contype="0" conaffinity="0" group="1" density="0" mesh="finger_dip"/>
                              <geom size="0.001" pos="-0.0011 0 0.03612" contype="0" conaffinity="0" group="1" density="0" rgba="1 1 1 1"/>
                              <!-- 指尖碰撞体：极小尺寸，最小化对爬起的影响 -->
                              <geom type="sphere" size="0.0015" pos="-0.0011 0 0.03612" group="2" friction="0.05 0.001 0.0001" rgba="1 0.5 0 0.2"/>
                            </body>
                          </body>
                          <body name="L_ring_abad" pos="-0.00151 -0.0112006 -0.14053" quat="0.000796327 0.999999683 0.0 0.0">
                            <inertial pos="-0.0018959 -9.8e-06 0.0066855" quat="0.707029 0.0104741 0.0104741 0.707029" mass="0.04" diaginertia="8.82e-06 7.37415e-06 2.64585e-06"/>
                            <joint name="L_ring_abad_joint" pos="0 0 0" axis="1 0 0" range="-0.174533 0" actuatorfrcrange="-2.0 2.0"/>
                            <geom type="mesh" contype="0" conaffinity="0" group="1" density="0" mesh="finger_abad"/>
                            <body name="L_ring_pip" pos="0.00048163 0 0.017575">
                              <inertial pos="-0.002884 1.5e-06 0.019997" quat="0.999936 0 -0.0113556 0" mass="0.004" diaginertia="7.00227e-07 6.8e-07 2.59773e-07"/>
                              <joint name="L_ring_pip_joint" pos="0 0 0" axis="0 1 0" range="0 1.5708" actuatorfrcrange="-2.0 2.0"/>
                              <geom type="mesh" contype="0" conaffinity="0" group="1" density="0" mesh="finger_pip"/>
                              <!-- 指节碰撞体：移除，避免影响爬起（只保留指尖碰撞体） -->
                              <!-- <geom type="sphere" size="0.003" pos="0.00048163 0 0.017575" group="2" friction="0.1 0.005 0.0001" rgba="1 0.5 0 0.2"/> -->
                              <body name="L_ring_dip" pos="-0.0015 0 0.036">
                                <inertial pos="0.000618 0 0.019239" mass="0.003" diaginertia="4e-07 4e-07 1.2e-07"/>
                                <joint name="L_ring_dip_joint" pos="0 0 0" axis="0 1 0" range="0 1.8326" actuatorfrcrange="-2.0 2.0"/>
                                <geom type="mesh" contype="0" conaffinity="0" group="1" density="0" mesh="finger_dip"/>
                                <geom size="0.001" pos="-0.0011 0 0.03612" contype="0" conaffinity="0" group="1" density="0" rgba="1 1 1 1"/>
                                <!-- 指尖碰撞体：暂时禁用，测试是否影响重心 -->
                                <!-- <geom type="sphere" size="0.0015" pos="-0.0011 0 0.03612" group="2" friction="0.05 0.001 0.0001" rgba="1 0.5 0 0.2"/> -->
                              </body>
                            </body>
                          </body>
                          <body name="L_pinky_abad" pos="0 -0.0301926 -0.1355" quat="0.000796327 0.999999683 0.0 0.0">
                            <inertial pos="-0.0018959 -9.8e-06 0.0066855" quat="0.707029 0.0104741 0.0104741 0.707029" mass="0.04" diaginertia="8.82e-06 7.37415e-06 2.64585e-06"/>
                            <joint name="L_pinky_abad_joint" pos="0 0 0" axis="1 0 0" range="-0.174533 0" actuatorfrcrange="-2.0 2.0"/>
                            <geom type="mesh" contype="0" conaffinity="0" group="1" density="0" mesh="finger_abad"/>
                            <body name="L_pinky_pip" pos="0.00048163 0 0.017575">
                              <inertial pos="-0.002884 1.5e-06 0.019997" quat="0.999936 0 -0.0113556 0" mass="0.004" diaginertia="7.00227e-07 6.8e-07 2.59773e-07"/>
                              <joint name="L_pinky_pip_joint" pos="0 0 0" axis="0 1 0" range="0 1.5708" actuatorfrcrange="-2.0 2.0"/>
                              <geom type="mesh" contype="0" conaffinity="0" group="1" density="0" mesh="finger_pip"/>
                              <!-- 指节碰撞体：移除，避免影响爬起（只保留指尖碰撞体） -->
                              <!-- <geom type="sphere" size="0.003" pos="0.00048163 0 0.017575" group="2" friction="0.1 0.005 0.0001" rgba="1 0.5 0 0.2"/> -->
                              <body name="L_pinky_dip" pos="-0.0015 0 0.036">
                                <inertial pos="0.000618 0 0.019239" mass="0.003" diaginertia="4e-07 4e-07 1.2e-07"/>
                                <joint name="L_pinky_dip_joint" pos="0 0 0" axis="0 1 0" range="0 1.8326" actuatorfrcrange="-2.0 2.0"/>
                                <geom type="mesh" contype="0" conaffinity="0" group="1" density="0" mesh="finger_dip"/>
                                <geom size="0.001" pos="-0.0011 0 0.03612" contype="0" conaffinity="0" group="1" density="0" rgba="1 1 1 1"/>
                                <!-- 指尖碰撞体：暂时禁用，测试是否影响重心 -->
                                <!-- <geom type="sphere" size="0.0015" pos="-0.0011 0 0.03612" group="2" friction="0.05 0.001 0.0001" rgba="1 0.5 0 0.2"/> -->
                              </body>
                            </body>
                          </body>
                        </body>
                      </body>
                    </body>
                  </body>
                </body>
              </body>
            </body>
            <body name="right_shoulder_pitch_link" pos="0.00299994 -0.142744 0.241589" quat="0.994522 -0.104528 0 0">
              <inertial pos="0.0062554 -0.051276 -0.0001565" quat="0.689166 0.721403 0.0337792 0.0590456" mass="0.816496" diaginertia="0.000493625 0.000439866 0.000414808"/>
              <joint name="right_shoulder_pitch_joint" pos="0 0 0" axis="0 1 0" range="-2.556 2.556" actuatorfrcrange="-36 36"/>
              <geom class="visual" type="mesh" contype="0" conaffinity="0" group="1" density="0" rgba="0.2 0.2 0.2 1" mesh="right_shoulder_pitch_link"/>
              <!-- <geom class="collision" group="2" type="mesh" rgba="0.2 0.2 0.2 1" mesh="right_shoulder_pitch_link"/> -->
              <body name="right_shoulder_roll_link" pos="0.031 -0.0495 0">
                <inertial pos="-0.0310194 0.0001343 -0.0847062" quat="0.705577 0.00295558 0.0106475 0.708547" mass="0.6574" diaginertia="0.00101497 0.000946383 0.000446448"/>
                <joint name="right_shoulder_roll_joint" pos="0 0 0" axis="1 0 0" range="-2.993 0.061" actuatorfrcrange="-36 36"/>
                <geom class="visual" type="mesh" contype="0" conaffinity="0" group="1" density="0" rgba="1 1 1 1" mesh="right_shoulder_roll_link"/>
                <geom class="collision" group="2" type="mesh" rgba="1 1 1 1" mesh="right_shoulder_roll_link"/>
                <body name="right_shoulder_yaw_link" pos="-0.031 0 -0.1212">
                  <inertial pos="0.010114 -0.005321 -0.0735041" quat="0.431335 0.125824 0.0115747 0.8933" mass="0.6682" diaginertia="0.00073122 0.000687907 0.000373973"/>
                  <joint name="right_shoulder_yaw_joint" pos="0 0 0" axis="0 0 1" range="-2.556 2.556" actuatorfrcrange="-24 24"/>
                  <geom class="visual" type="mesh" contype="0" conaffinity="0" group="1" density="0" rgba="1 1 1 1" mesh="right_shoulder_yaw_link"/>
                  <geom class="collision" group="2" type="mesh" rgba="1 1 1 1" mesh="right_shoulder_yaw_link"/>
                  <body name="right_elbow_link" pos="0.014 -0.000199986 -0.083">
                    <inertial pos="-0.0141925 -0.0028942 -0.0864652" quat="0.97364 0.127628 0.0179354 -0.188189" mass="0.651254" diaginertia="0.000769797 0.000738403 0.0003346"/>
                    <joint name="right_elbow_joint" pos="0 0 0" axis="0 1 0" range="-2.556 0" actuatorfrcrange="-24 24"/>
                    <geom class="visual" type="mesh" contype="0" conaffinity="0" group="1" density="0" rgba="1 1 1 1" mesh="right_elbow_link"/>
                    <geom class="collision" group="2" type="mesh" rgba="1 1 1 1" mesh="right_elbow_link"/>
                    <body name="right_wrist_yaw_link" pos="-0.014 0.00019755 -0.120694">
                      <inertial pos="0.0003189 -0.0026774 -0.0321977" quat="0.984821 0.169683 0.00985909 -0.0351862" mass="0.322834" diaginertia="0.000256045 0.000210476 0.000171479"/>
                      <joint name="right_wrist_yaw_joint" pos="0 0 0" axis="0 0 1" range="-2.556 2.556" actuatorfrcrange="-24 24" ref="-1.57"/>
                      <geom class="visual" type="mesh" contype="0" conaffinity="0" group="1" density="0" rgba="1 1 1 1" mesh="right_wrist_yaw_link"/>
                      <geom class="collision" group="2" type="mesh" rgba="1 1 1 1" mesh="right_wrist_yaw_link"/>
                      <body name="right_wrist_pitch_link" pos="0 0 -0.0803">
                        <inertial pos="-0.0005283 1.49e-05 0.0002824" quat="0 0.752259 0 0.658868" mass="0.2189" diaginertia="6.44393e-05 6.38e-05 5.06607e-05"/>
                        <joint name="right_wrist_pitch_joint" pos="0 0 0" axis="0 1 0" range="-0.558 0.558" actuatorfrcrange="-4.8 4.8"/>
                        <geom class="visual" type="mesh" contype="0" conaffinity="0" group="1" density="0" rgba="0.2 0.2 0.2 1" mesh="right_wrist_pitch_link"/>
                        <!-- <geom class="collision" group="2" type="mesh" rgba="0.2 0.2 0.2 1" mesh="right_wrist_pitch_link"/> -->
                        <body name="right_wrist_roll_link" pos="0.00085 0 0">
                          <inertial pos="0.0036751 0.0015642 -0.0906068" quat="0.795067 -0.00736773 0.00761083 0.60643" mass="0.258845" diaginertia="0.000573327 0.000481054 0.000169319"/>
                          <joint name="right_wrist_roll_joint" pos="0 0 0" axis="1 0 0" range="-1.544 1.544" actuatorfrcrange="-4.8 4.8"/>
                          <geom  class="visual" type="mesh" contype="0" conaffinity="0" group="1" density="0" rgba="0.2 0.2 0.2 1" mesh="right_wrist_roll_extend_link"/>
                          <geom  class="visual" type="mesh" contype="0" conaffinity="0" group="1" density="0" rgba="0.2 0.2 0.2 1" mesh="right_wrist_roll_extend_link1"/>
                          <!-- <geom  class="collision" group="2" type="mesh" rgba="0.2 0.2 0.2 1" mesh="right_wrist_roll_yellow_link"/> -->
                          
                          <geom  class="visual" pos="0 0 -0.046" quat="0.000796327 0.999999683 0.0 0.0" type="mesh" contype="0" conaffinity="0" group="1" density="0" mesh="r_palm"/>
                          <!-- 手掌碰撞体：暂时禁用，避免影响平衡 -->
                          <!-- <geom size="0.015 0.03 0.03" pos="0 -9.07812e-05 -0.103" quat="0.000796327 0.999999683 0.0 0.0" type="box" group="3" rgba="1 0.5 0 0.3"/> -->
                            <geom class="visual" pos="-0.0025 -0.00810376 -0.142535" quat="0.000796327 0.999999683 0.0 0.0" type="mesh" contype="0" conaffinity="0" group="1" density="0" mesh="finger_abad"/>
                            <body name="R_thumb_roll" pos="0 -0.0185967 -0.0935214" quat="0.000796327 0.999999683 0.0 0.0">
                            <inertial pos="-0.003851 -0.000311 0.008401" quat="0.516685 0.501033 -0.483834 0.497903" mass="0.025" diaginertia="3.69257e-06 2.85892e-06 2.00851e-06"/>
                            <joint name="R_thumb_roll_joint" pos="0 0 0" axis="1 0 0" range="-0.174533 0.872665" actuatorfrcrange="-2.0 2.0"/>
                            <geom class="visual" type="mesh" contype="0" conaffinity="0" group="1" density="0" mesh="r_thumb_roll"/>
                            <body name="R_thumb_abad" pos="0.020801 0.004292 -0.00052506">
                              <inertial pos="-1.2e-06 0.0129928 -0.0041829" quat="0.996767 -0.0803509 0 0" mass="0.0056" diaginertia="1.03e-06 8.89737e-07 5.10263e-07"/>
                              <joint name="R_thumb_abad_joint" pos="0 0 0" axis="0 0 1" range="-1.74533 0" actuatorfrcrange="-2.0 2.0"/>
                              <geom class="visual" type="mesh" contype="0" conaffinity="0" group="1" density="0" mesh="thumb_abad"/>
                              <body name="R_thumb_mcp" pos="0 0.0265 -0.005275">
                                <inertial pos="-1.83e-05 0.0225829 0.0024013" quat="0.691728 0.722157 -0.000532546 -0.000351102" mass="0.0511" diaginertia="1.274e-05 1.12221e-05 4.70793e-06"/>
                                <joint name="R_thumb_mcp_joint" pos="0 0 0" axis="1 0 0" range="0 0.855211" actuatorfrcrange="-2.0 2.0"/>
                                <geom class="visual" type="mesh" contype="0" conaffinity="0" group="1" density="0" mesh="thumb_mcp"/>
                                <!-- <geom size="0.0145 0.021 0.01625" pos="0 0.0065 0.00237" type="box"/> -->
                                <body name="R_thumb_pip" pos="0 0.036231 0.0036755">
                                  <inertial pos="-1e-06 0.014461 -0.00415" quat="0.752037 0.659121 0 0" mass="0.011" diaginertia="1.34e-06 1.31926e-06 7.80742e-07"/>
                                  <joint name="R_thumb_pip_joint" pos="0 0 0" axis="1 0 0" range="0 1.13446" actuatorfrcrange="-2.0 2.0"/>
                                  <geom class="visual" type="mesh" contype="0" conaffinity="0" group="1" density="0" rgba="1 1 1 1" mesh="thumb_pip"/>
                                  <!-- <geom size="0.0095 0.0175 0.01125" pos="0 0.0116 -0.0032" quat="0.995004 -0.0998334 0 0" type="box" rgba="1 1 1 1"/> -->
                                  <body name="R_thumb_dip" pos="0 0.026468 -0.0073106">
                                    <inertial pos="-3e-06 0.010392 -0.001614" quat="0.323685 0.628672 -0.628672 0.323685" mass="0.007" diaginertia="5.54189e-07 5.2e-07 2.15811e-07"/>
                                    <joint name="R_thumb_dip_joint" pos="0 0 0" axis="1 0 0" range="0 1.13446" actuatorfrcrange="-2.0 2.0"/>
                                    <geom class="visual" type="mesh" contype="0" conaffinity="0" group="1" density="0" rgba="1 1 1 1" mesh="thumb_dip"/>
                                    <geom size="0.001" pos="0 0.02392 -0.01158" contype="0" conaffinity="0" group="1" density="0" rgba="1 1 1 1"/>
                                    <!-- 指尖碰撞体：极小尺寸，最小化对爬起的影响 -->
                                    <geom type="sphere" size="0.0015" pos="0 0.02392 -0.01158" group="2" friction="0.05 0.001 0.0001" rgba="1 0.5 0 0.2"/>
                                  </body>
                                </body>
                              </body>
                            </body>
                          </body>
                          <body name="R_index_abad" pos="0 -0.0271005 -0.140505" quat="0.000796327 0.999999683 0.0 0.0">
                            <inertial pos="-0.0018959 -9.8e-06 0.0066855" quat="0.707029 0.0104741 0.0104741 0.707029" mass="0.04" diaginertia="8.82e-06 7.37415e-06 2.64585e-06"/>
                            <joint name="R_index_abad_joint" pos="0 0 0" axis="1 0 0" range="-0.20944 0" actuatorfrcrange="-2.0 2.0"/>
                            <geom class="visual" type="mesh" contype="0" conaffinity="0" group="1" density="0" mesh="finger_abad"/>
                            <body name="R_index_pip" pos="0.00048163 0 0.017575">
                              <inertial pos="-0.002884 1.5e-06 0.019997" quat="0.999936 0 -0.0113556 0" mass="0.004" diaginertia="7.00227e-07 6.8e-07 2.59773e-07"/>
                              <joint name="R_index_pip_joint" pos="0 0 0" axis="0 1 0" range="0 1.5708" actuatorfrcrange="-2.0 2.0"/>
                              <geom class="visual" type="mesh" contype="0" conaffinity="0" group="1" density="0" mesh="finger_pip"/>
                              <!-- 指节碰撞体：移除，避免影响爬起（只保留指尖碰撞体） -->
                              <!-- <geom type="sphere" size="0.003" pos="0.00048163 0 0.017575" group="2" friction="0.1 0.005 0.0001" rgba="1 0.5 0 0.2"/> -->
                              <body name="R_index_dip" pos="-0.0015 0 0.036">
                                <inertial pos="0.000618 0 0.019239" mass="0.003" diaginertia="4e-07 4e-07 1.2e-07"/>
                                <joint name="R_index_dip_joint" pos="0 0 0" axis="0 1 0" range="0 1.8326" actuatorfrcrange="-2.0 2.0"/>
                                <geom class="visual" type="mesh" contype="0" conaffinity="0" group="1" density="0" mesh="finger_dip"/>
                                <geom size="0.001" pos="-0.0011 0 0.03612" contype="0" conaffinity="0" group="1" density="0" rgba="1 1 1 1"/>
                                <!-- 指尖碰撞体：暂时禁用，测试是否影响重心 -->
                                <!-- <geom type="sphere" size="0.0015" pos="-0.0011 0 0.03612" group="2" friction="0.05 0.001 0.0001" rgba="1 0.5 0 0.2"/> -->
                              </body>
                            </body>
                          </body>
                          <body name="R_middle_pip" pos="-0.00201837 -0.00813175 -0.16011" quat="0.000796327 0.999999683 0.0 0.0">
                            <inertial pos="-0.002884 1.5e-06 0.019997" quat="0.999936 0 -0.0113556 0" mass="0.004" diaginertia="7.00227e-07 6.8e-07 2.59773e-07"/>
                            <joint name="R_middle_pip_joint" pos="0 0 0" axis="0 1 0" range="0 1.5708" actuatorfrcrange="-2.0 2.0"/>
                            <geom class="visual" type="mesh" contype="0" conaffinity="0" group="1" density="0" mesh="finger_pip"/>
                            <!-- 指节碰撞体：移除，避免影响爬起（只保留指尖碰撞体） -->
                            <!-- <geom type="sphere" size="0.003" pos="-0.00201837 -0.00813175 -0.16011" quat="0.000796327 0.999999683 0.0 0.0" group="2" friction="0.1 0.005 0.0001" rgba="1 0.5 0 0.2"/> -->
                            <body name="R_middle_dip" pos="-0.0015 0 0.036">
                              <inertial pos="0.000618 0 0.019239" mass="0.003" diaginertia="4e-07 4e-07 1.2e-07"/>
                              <joint name="R_middle_dip_joint" pos="0 0 0" axis="0 1 0" range="0 1.8326" actuatorfrcrange="-2.0 2.0"/>
                              <geom class="visual" type="mesh" contype="0" conaffinity="0" group="1" density="0" mesh="finger_dip"/>
                              <geom size="0.001" pos="-0.0011 0 0.03612" contype="0" conaffinity="0" group="1" density="0" rgba="1 1 1 1"/>
                              <!-- 指尖碰撞体：极小尺寸，最小化对爬起的影响 -->
                              <geom type="sphere" size="0.0015" pos="-0.0011 0 0.03612" group="2" friction="0.05 0.001 0.0001" rgba="1 0.5 0 0.2"/>
                            </body>
                          </body>
                          <body name="R_ring_abad" pos="-0.00151 0.0108994 -0.140565" quat="0.000796327 0.999999683 0.0 0.0">
                            <inertial pos="-0.0018959 -9.8e-06 0.0066855" quat="0.707029 0.0104741 0.0104741 0.707029" mass="0.04" diaginertia="8.82e-06 7.37415e-06 2.64585e-06"/>
                            <joint name="R_ring_abad_joint" pos="0 0 0" axis="1 0 0" range="0 0.174533" actuatorfrcrange="-2.0 2.0"/>
                            <geom class="visual" type="mesh" contype="0" conaffinity="0" group="1" density="0" mesh="finger_abad"/>
                            <body name="R_ring_pip" pos="0.00048163 0 0.017575">
                              <inertial pos="-0.002884 1.5e-06 0.019997" quat="0.999936 0 -0.0113556 0" mass="0.004" diaginertia="7.00227e-07 6.8e-07 2.59773e-07"/>
                              <joint name="R_ring_pip_joint" pos="0 0 0" axis="0 1 0" range="0 1.5708" actuatorfrcrange="-2.0 2.0"/>
                              <geom class="visual" type="mesh" contype="0" conaffinity="0" group="1" density="0" mesh="finger_pip"/>
                              <!-- 指节碰撞体：移除，避免影响爬起（只保留指尖碰撞体） -->
                              <!-- <geom type="sphere" size="0.003" pos="0.00048163 0 0.017575" group="2" friction="0.1 0.005 0.0001" rgba="1 0.5 0 0.2"/> -->
                              <body name="R_ring_dip" pos="-0.0015 0 0.036">
                                <inertial pos="0.000618 0 0.019239" mass="0.003" diaginertia="4e-07 4e-07 1.2e-07"/>
                                <joint name="R_ring_dip_joint" pos="0 0 0" axis="0 1 0" range="0 1.8326" actuatorfrcrange="-2.0 2.0"/>
                                <geom class="visual" type="mesh" contype="0" conaffinity="0" group="1" density="0" mesh="finger_dip"/>
                                <geom size="0.001" pos="-0.0011 0 0.03612" contype="0" conaffinity="0" group="1" density="0" rgba="1 1 1 1"/>
                                <!-- 指尖碰撞体：暂时禁用，测试是否影响重心 -->
                                <!-- <geom type="sphere" size="0.0015" pos="-0.0011 0 0.03612" group="2" friction="0.05 0.001 0.0001" rgba="1 0.5 0 0.2"/> -->
                              </body>
                            </body>
                          </body>
                          <body name="R_pinky_abad" pos="0 0.0299073 -0.135596" quat="0.000796327 0.999999683 0.0 0.0">
                            <inertial pos="-0.0018959 -9.8e-06 0.0066855" quat="0.707029 0.0104741 0.0104741 0.707029" mass="0.04" diaginertia="8.82e-06 7.37415e-06 2.64585e-06"/>
                            <joint name="R_pinky_abad_joint" pos="0 0 0" axis="1 0 0" range="0 0.174533" actuatorfrcrange="-2.0 2.0"/>
                            <geom class="visual" type="mesh" contype="0" conaffinity="0" group="1" density="0" mesh="finger_abad"/>
                            <body name="R_pinky_pip" pos="0.00048163 0 0.017575">
                              <inertial pos="-0.002884 1.5e-06 0.019997" quat="0.999936 0 -0.0113556 0" mass="0.004" diaginertia="7.00227e-07 6.8e-07 2.59773e-07"/>
                              <joint name="R_pinky_pip_joint" pos="0 0 0" axis="0 1 0" range="0 1.5708" actuatorfrcrange="-2.0 2.0"/>
                              <geom class="visual" type="mesh" contype="0" conaffinity="0" group="1" density="0" mesh="finger_pip"/>
                              <!-- 指节碰撞体：移除，避免影响爬起（只保留指尖碰撞体） -->
                              <!-- <geom type="sphere" size="0.003" pos="0.00048163 0 0.017575" group="2" friction="0.1 0.005 0.0001" rgba="1 0.5 0 0.2"/> -->
                              <body name="R_pinky_dip" pos="-0.0015 0 0.036">
                                <inertial pos="0.000618 0 0.019239" mass="0.003" diaginertia="4e-07 4e-07 1.2e-07"/>
                                <joint name="R_pinky_dip_joint" pos="0 0 0" axis="0 1 0" range="0 1.8326" actuatorfrcrange="-2.0 2.0"/>
                                <geom class="visual" type="mesh" contype="0" conaffinity="0" group="1" density="0" mesh="finger_dip"/>
                                <geom size="0.001" pos="-0.0011 0 0.03612" contype="0" conaffinity="0" group="1" density="0" rgba="1 1 1 1"/>
                                <!-- 指尖碰撞体：暂时禁用，测试是否影响重心 -->
                                <!-- <geom type="sphere" size="0.0015" pos="-0.0011 0 0.03612" group="2" friction="0.05 0.001 0.0001" rgba="1 0.5 0 0.2"/> -->
                              </body>
                            </body>
                          </body>
                        </body>
                      </body>
                    </body>
                  </body>
                </body>
              </body>
            </body>
            <body name="head_yaw_link" pos="0.00804785 -8.23423e-05 0.303917">
              <inertial pos="-0.0154828 -0.000676 -0.0709835" quat="0.571848 0.741855 -0.169331 0.306541" mass="0.399689" diaginertia="0.000842925 0.000751115 0.000638059"/>
              <joint name="head_yaw_joint" pos="0 0 0" axis="0 0 1" range="-0.488 0.488" actuatorfrcrange="-2.6 2.6"/>
              <geom class="visual" type="mesh" contype="0" conaffinity="0" group="1" density="0" rgba="0.2 0.2 0.2 1" mesh="head_yaw_link"/>
              <!-- <geom class="collision" group="2" type="mesh" rgba="0.2 0.2 0.2 1" mesh="head_yaw_link"/> -->
              <body name="head_pitch_link" pos="0 0 0.092404" quat="1 0 0 -9.2155e-06">
                <inertial pos="0.0050269 0.0001177 0.0059427" quat="0.89409 0.0513108 0.365747 0.253377" mass="1.28755" diaginertia="0.00387255 0.00380113 0.00327372"/>
                <joint name="head_pitch_joint" pos="0 0 0" axis="0 1 0" range="-0.488 0.488" actuatorfrcrange="-0.6 0.6"/>
                <geom class="visual" type="mesh" contype="0" conaffinity="0" group="1" density="0" rgba="0 0 0 0.6" mesh="head_pitch_link"/>
                <!-- <geom class="collision" group="2" type="mesh" rgba="0 0 0 0.6" mesh="head_pitch_link"/> -->
                <site name="imu_2" pos="0.026335 0 0.016849" group="3"/>
                <geom class="visual" group="3" pos="0.026335 0 0.016849" quat="1 0 0 0" type="mesh" contype="0" conaffinity="0"  density="0" rgba="0.752941 0.752941 0.752941 1" mesh="imu_in_head_link"/>
                <geom class="visual" pos="0.055559 -0.011 -0.0485" quat="0.29159 0.645851 0.641639 0.293515" type="mesh" contype="0" conaffinity="0" group="1" density="0" rgba="0.647059 0.619608 0.588235 1" mesh="RGBD_in_head_link"/>
                <geom class="visual" pos="0.05058 0.03013 0.032504" quat="0.497273 -0.502661 0.507034 -0.492919" type="mesh" contype="0" conaffinity="0" group="1" density="0" rgba="0.752941 0.752941 0.752941 1" mesh="RGB_REAR_link"/>
                <geom class="visual" pos="-0.078615 0 0.0015359" quat="0.713966 -8.41125e-07 -0.70018 -1.01141e-06" type="mesh" contype="0" conaffinity="0" group="1" density="0" rgba="0.866667 0.866667 0.890196 1" mesh="RGB_REAR_link"/>
              </body>
            </body>
          </body>
        </body>
      </body>
    </body>
  </worldbody>
  
  <!-- 排除手指之间的碰撞，避免影响初始姿态 -->
  <contact>
    <exclude body1="L_thumb_dip" body2="L_index_dip"/>
    <exclude body1="L_thumb_dip" body2="L_middle_dip"/>
    <exclude body1="L_thumb_dip" body2="L_ring_dip"/>
    <exclude body1="L_thumb_dip" body2="L_pinky_dip"/>
    <exclude body1="L_index_dip" body2="L_middle_dip"/>
    <exclude body1="L_index_dip" body2="L_ring_dip"/>
    <exclude body1="L_index_dip" body2="L_pinky_dip"/>
    <exclude body1="L_middle_dip" body2="L_ring_dip"/>
    <exclude body1="L_middle_dip" body2="L_pinky_dip"/>
    <exclude body1="L_ring_dip" body2="L_pinky_dip"/>
    
    <exclude body1="R_thumb_dip" body2="R_index_dip"/>
    <exclude body1="R_thumb_dip" body2="R_middle_dip"/>
    <exclude body1="R_thumb_dip" body2="R_ring_dip"/>
    <exclude body1="R_thumb_dip" body2="R_pinky_dip"/>
    <exclude body1="R_index_dip" body2="R_middle_dip"/>
    <exclude body1="R_index_dip" body2="R_ring_dip"/>
    <exclude body1="R_index_dip" body2="R_pinky_dip"/>
    <exclude body1="R_middle_dip" body2="R_ring_dip"/>
    <exclude body1="R_middle_dip" body2="R_pinky_dip"/>
    <exclude body1="R_ring_dip" body2="R_pinky_dip"/>
    
    <!-- 排除指节之间的碰撞 -->
    <exclude body1="L_index_pip" body2="L_middle_pip"/>
    <exclude body1="L_index_pip" body2="L_ring_pip"/>
    <exclude body1="L_index_pip" body2="L_pinky_pip"/>
    <exclude body1="L_middle_pip" body2="L_ring_pip"/>
    <exclude body1="L_middle_pip" body2="L_pinky_pip"/>
    <exclude body1="L_ring_pip" body2="L_pinky_pip"/>
    
    <exclude body1="R_index_pip" body2="R_middle_pip"/>
    <exclude body1="R_index_pip" body2="R_ring_pip"/>
    <exclude body1="R_index_pip" body2="R_pinky_pip"/>
    <exclude body1="R_middle_pip" body2="R_ring_pip"/>
    <exclude body1="R_middle_pip" body2="R_pinky_pip"/>
    <exclude body1="R_ring_pip" body2="R_pinky_pip"/>
  </contact>
  
  <actuator>
    <motor class="x2" name="motor_left_hip_pitch_joint" joint="left_hip_pitch_joint" ctrlrange="-118 118"/>
    <motor class="x2" name="motor_left_hip_roll_joint" joint="left_hip_roll_joint" ctrlrange="-118 118"/>
    <motor class="x2" name="motor_left_hip_yaw_joint" joint="left_hip_yaw_joint" ctrlrange="-118 118"/>
    <motor class="x2" name="motor_left_knee_joint" joint="left_knee_joint" ctrlrange="-118 118"/>
    <motor class="x2" name="motor_left_ankle_pitch_joint" joint="left_ankle_pitch_joint" ctrlrange="-36 36"/>
    <motor class="x2" name="motor_left_ankle_roll_joint" joint="left_ankle_roll_joint" ctrlrange="-24 24"/>

    <motor class="x2" name="motor_right_hip_pitch_joint" joint="right_hip_pitch_joint" ctrlrange="-118 118"/>
    <motor class="x2" name="motor_right_hip_roll_joint" joint="right_hip_roll_joint" ctrlrange="-118 118"/>
    <motor class="x2" name="motor_right_hip_yaw_joint" joint="right_hip_yaw_joint" ctrlrange="-118 118"/>
    <motor class="x2" name="motor_right_knee_joint" joint="right_knee_joint" ctrlrange="-118 118"/>
    <motor class="x2" name="motor_right_ankle_pitch_joint" joint="right_ankle_pitch_joint" ctrlrange="-36 36"/>
    <motor class="x2" name="motor_right_ankle_roll_joint" joint="right_ankle_roll_joint" ctrlrange="-24 24"/>

    <motor class="x2" name="motor_waist_yaw_joint" joint="waist_yaw_joint" ctrlrange="-118 118"/>
    <motor class="x2" name="motor_waist_pitch_joint" joint="waist_pitch_joint" ctrlrange="-48 48"/>
    <motor class="x2" name="motor_waist_roll_joint" joint="waist_roll_joint" ctrlrange="-48 48"/>

    <motor class="x2" name="motor_head_yaw_joint" joint="head_yaw_joint" ctrlrange="-2.6 2.6"/>
    <motor class="x2" name="motor_head_pitch_joint" joint="head_pitch_joint" ctrlrange="-0.6 0.6"/>

    <motor class="x2" name="motor_left_shoulder_pitch_joint" joint="left_shoulder_pitch_joint" ctrlrange="-36 36"/>
    <motor class="x2" name="motor_left_shoulder_roll_joint" joint="left_shoulder_roll_joint" ctrlrange="-36 36"/>
    <motor class="x2" name="motor_left_shoulder_yaw_joint" joint="left_shoulder_yaw_joint" ctrlrange="-24 24"/>
    <motor class="x2" name="motor_left_elbow_joint" joint="left_elbow_joint" ctrlrange="-24 24"/>
    <motor class="x2" name="motor_left_wrist_yaw_joint" joint="left_wrist_yaw_joint" ctrlrange="-24 24"/>
    <motor class="x2" name="motor_left_wrist_pitch_joint" joint="left_wrist_pitch_joint" ctrlrange="-2.2 2.2"/>
    <motor class="x2" name="motor_left_wrist_roll_joint" joint="left_wrist_roll_joint" ctrlrange="-2.2 2.2"/>

    <motor class="x2" name="motor_right_shoulder_pitch_joint" joint="right_shoulder_pitch_joint" ctrlrange="-36 36"/>
    <motor class="x2" name="motor_right_shoulder_roll_joint" joint="right_shoulder_roll_joint" ctrlrange="-36 36"/>
    <motor class="x2" name="motor_right_shoulder_yaw_joint" joint="right_shoulder_yaw_joint" ctrlrange="-24 24"/>
    <motor class="x2" name="motor_right_elbow_joint" joint="right_elbow_joint" ctrlrange="-24 24"/>
    <motor class="x2" name="motor_right_wrist_yaw_joint" joint="right_wrist_yaw_joint" ctrlrange="-24 24"/>
    <motor class="x2" name="motor_right_wrist_pitch_joint" joint="right_wrist_pitch_joint" ctrlrange="-2.2 2.2"/>
    <motor class="x2" name="motor_right_wrist_roll_joint" joint="right_wrist_roll_joint" ctrlrange="-2.2 2.2"/>

    <!-- Hand关节：使用position执行器（位置型），MuJoCo内部处理PD控制 -->
    <position name="motor_L_thumb_mcp" joint="L_thumb_mcp_joint" kp="100"/>
    <position name="motor_L_thumb_roll" joint="L_thumb_roll_joint" kp="100"/>
    <position name="motor_L_thumb_abad" joint="L_thumb_abad_joint" kp="100"/>
    <position name="motor_L_index_abad" joint="L_index_abad_joint" kp="100"/>
    <position name="motor_L_index_pip" joint="L_index_pip_joint" kp="100"/>
    <position name="motor_L_middle_pip" joint="L_middle_pip_joint" kp="100"/>
    <position name="motor_L_ring_abad" joint="L_ring_abad_joint" kp="100"/>
    <position name="motor_L_ring_pip" joint="L_ring_pip_joint" kp="100"/>
    <position name="motor_L_pinky_abad" joint="L_pinky_abad_joint" kp="100"/>
    <position name="motor_L_pinky_pip" joint="L_pinky_pip_joint" kp="100"/>

    <position name="motor_R_thumb_mcp" joint="R_thumb_mcp_joint" kp="100"/>
    <position name="motor_R_thumb_roll" joint="R_thumb_roll_joint" kp="100"/>
    <position name="motor_R_thumb_abad" joint="R_thumb_abad_joint" kp="100"/>
    <position name="motor_R_index_abad" joint="R_index_abad_joint" kp="100"/>
    <position name="motor_R_index_pip" joint="R_index_pip_joint" kp="100"/>
    <position name="motor_R_middle_pip" joint="R_middle_pip_joint" kp="100"/>
    <position name="motor_R_ring_abad" joint="R_ring_abad_joint" kp="100"/>
    <position name="motor_R_ring_pip" joint="R_ring_pip_joint" kp="100"/>
    <position name="motor_R_pinky_abad" joint="R_pinky_abad_joint" kp="100"/>
    <position name="motor_R_pinky_pip" joint="R_pinky_pip_joint" kp="100"/>

  </actuator>
  <sensor>
    <!-- <gyro name="imu0-gyro" site="imu_0" cutoff="7.85"/>
    <accelerometer name="imu0-acc" site="imu_0" cutoff="157"/>
    <framequat name="imu0-quat" objtype="site" objname="imu_0"/>

    <gyro name="imu1-gyro" site="imu_1" cutoff="7.85"/>
    <accelerometer name="imu1-acc" site="imu_1" cutoff="157"/>
    <framequat name="imu1-quat" objtype="site" objname="imu_1"/> -->

    <framequat name="body-orientation" objtype="site" objname="imu_0" noise="0"/>
    <gyro name="body-angular-velocity" site="imu_0" noise="0.001"/>
    <framepos name="body-linear-pos" objtype="site" objname="imu_0"/>
    <velocimeter name="body-linear-vel" site="imu_0"/>
    <accelerometer name="body-linear-acceleration" site="imu_0" noise="0.001"/>
    
    <jointpos name = 'jointpos_left_hip_pitch_joint' joint = 'left_hip_pitch_joint' noise = "0" />
    <jointpos name = 'jointpos_left_hip_roll_joint' joint = 'left_hip_roll_joint' noise = "0" />
    <jointpos name = 'jointpos_left_hip_yaw_joint' joint = 'left_hip_yaw_joint' noise = "0" />
    <jointpos name = 'jointpos_left_knee_joint' joint = 'left_knee_joint' noise = "0" />
    <jointpos name = 'jointpos_left_ankle_pitch_joint' joint = 'left_ankle_pitch_joint' noise = "0" />
    <jointpos name = 'jointpos_left_ankle_roll_joint' joint = 'left_ankle_roll_joint' noise = "0" />

    <jointpos name = 'jointpos_right_hip_pitch_joint' joint = 'right_hip_pitch_joint' noise = "0" />
    <jointpos name = 'jointpos_right_hip_roll_joint' joint = 'right_hip_roll_joint' noise = "0" />
    <jointpos name = 'jointpos_right_hip_yaw_joint' joint = 'right_hip_yaw_joint' noise = "0" />
    <jointpos name = 'jointpos_right_knee_joint' joint = 'right_knee_joint' noise = "0" />
    <jointpos name = 'jointpos_right_ankle_pitch_joint' joint = 'right_ankle_pitch_joint' noise = "0" />
    <jointpos name = 'jointpos_right_ankle_roll_joint' joint = 'right_ankle_roll_joint' noise = "0" />

    <jointpos name = 'jointpos_waist_yaw_joint' joint = 'waist_yaw_joint' noise = "0" />
    <jointpos name = 'jointpos_waist_pitch_joint' joint = 'waist_pitch_joint' noise = "0" />
    <jointpos name = 'jointpos_waist_roll_joint' joint = 'waist_roll_joint' noise = "0" />

    <jointpos name = 'jointpos_head_yaw_joint' joint = 'head_yaw_joint' noise = "0" />
    <jointpos name = 'jointpos_head_pitch_joint' joint = 'head_pitch_joint' noise = "0" />

    <jointpos name = 'jointpos_left_shoulder_pitch_joint' joint = 'left_shoulder_pitch_joint' noise = "0" />
    <jointpos name = 'jointpos_left_shoulder_roll_joint' joint = 'left_shoulder_roll_joint' noise = "0" />
    <jointpos name = 'jointpos_left_shoulder_yaw_joint' joint = 'left_shoulder_yaw_joint' noise = "0" />
    <jointpos name = 'jointpos_left_elbow_joint' joint = 'left_elbow_joint' noise = "0" />
    <jointpos name = 'jointpos_left_wrist_yaw_joint' joint = 'left_wrist_yaw_joint' noise = "0" />
    <jointpos name = 'jointpos_left_wrist_pitch_joint' joint = 'left_wrist_pitch_joint' noise = "0" />
    <jointpos name = 'jointpos_left_wrist_roll_joint' joint = 'left_wrist_roll_joint' noise = "0" />

    <jointpos name = 'jointpos_right_shoulder_pitch_joint' joint = 'right_shoulder_pitch_joint' noise = "0" />
    <jointpos name = 'jointpos_right_shoulder_roll_joint' joint = 'right_shoulder_roll_joint' noise = "0" />
    <jointpos name = 'jointpos_right_shoulder_yaw_joint' joint = 'right_shoulder_yaw_joint' noise = "0" />
    <jointpos name = 'jointpos_right_elbow_joint' joint = 'right_elbow_joint' noise = "0" />
    <jointpos name = 'jointpos_right_wrist_yaw_joint' joint = 'right_wrist_yaw_joint' noise = "0" />
    <jointpos name = 'jointpos_right_wrist_pitch_joint' joint = 'right_wrist_pitch_joint' noise = "0" />
    <jointpos name = 'jointpos_right_wrist_roll_joint' joint = 'right_wrist_roll_joint' noise = "0" />

    <jointvel name = 'jointvel_left_hip_pitch_joint' joint = 'left_hip_pitch_joint' noise = "0" />
    <jointvel name = 'jointvel_left_hip_roll_joint' joint = 'left_hip_roll_joint' noise = "0" />
    <jointvel name = 'jointvel_left_hip_yaw_joint' joint = 'left_hip_yaw_joint' noise = "0" />
    <jointvel name = 'jointvel_left_knee_joint' joint = 'left_knee_joint' noise = "0" />
    <jointvel name = 'jointvel_left_ankle_pitch_joint' joint = 'left_ankle_pitch_joint' noise = "0" />
    <jointvel name = 'jointvel_left_ankle_roll_joint' joint = 'left_ankle_roll_joint' noise = "0" />

    <jointvel name = 'jointvel_right_hip_pitch_joint' joint = 'right_hip_pitch_joint' noise = "0" />
    <jointvel name = 'jointvel_right_hip_roll_joint' joint = 'right_hip_roll_joint' noise = "0" />
    <jointvel name = 'jointvel_right_hip_yaw_joint' joint = 'right_hip_yaw_joint' noise = "0" />
    <jointvel name = 'jointvel_right_knee_joint' joint = 'right_knee_joint' noise = "0" />
    <jointvel name = 'jointvel_right_ankle_pitch_joint' joint = 'right_ankle_pitch_joint' noise = "0" />
    <jointvel name = 'jointvel_right_ankle_roll_joint' joint = 'right_ankle_roll_joint' noise = "0" />

    <jointvel name = 'jointvel_waist_yaw_joint' joint = 'waist_yaw_joint' noise = "0" />
    <jointvel name = 'jointvel_waist_pitch_joint' joint = 'waist_pitch_joint' noise = "0" />
    <jointvel name = 'jointvel_waist_roll_joint' joint = 'waist_roll_joint' noise = "0" />

    <jointvel name = 'jointvel_head_yaw_joint' joint = 'head_yaw_joint' noise = "0" />
    <jointvel name = 'jointvel_head_pitch_joint' joint = 'head_pitch_joint' noise = "0" />

    <jointvel name = 'jointvel_left_shoulder_pitch_joint' joint = 'left_shoulder_pitch_joint' noise = "0" />
    <jointvel name = 'jointvel_left_shoulder_roll_joint' joint = 'left_shoulder_roll_joint' noise = "0" />
    <jointvel name = 'jointvel_left_shoulder_yaw_joint' joint = 'left_shoulder_yaw_joint' noise = "0" />
    <jointvel name = 'jointvel_left_elbow_joint' joint = 'left_elbow_joint' noise = "0" />
    <jointvel name = 'jointvel_left_wrist_yaw_joint' joint = 'left_wrist_yaw_joint' noise = "0" />
    <jointvel name = 'jointvel_left_wrist_pitch_joint' joint = 'left_wrist_pitch_joint' noise = "0" />
    <jointvel name = 'jointvel_left_wrist_roll_joint' joint = 'left_wrist_roll_joint' noise = "0" />

    <jointvel name = 'jointvel_right_shoulder_pitch_joint' joint = 'right_shoulder_pitch_joint' noise = "0" />
    <jointvel name = 'jointvel_right_shoulder_roll_joint' joint = 'right_shoulder_roll_joint' noise = "0" />
    <jointvel name = 'jointvel_right_shoulder_yaw_joint' joint = 'right_shoulder_yaw_joint' noise = "0" />
    <jointvel name = 'jointvel_right_elbow_joint' joint = 'right_elbow_joint' noise = "0" />
    <jointvel name = 'jointvel_right_wrist_yaw_joint' joint = 'right_wrist_yaw_joint' noise = "0" />
    <jointvel name = 'jointvel_right_wrist_pitch_joint' joint = 'right_wrist_pitch_joint' noise = "0" />
    <jointvel name = 'jointvel_right_wrist_roll_joint' joint = 'right_wrist_roll_joint' noise = "0" />

    <jointvel name='jointvel_L_thumb_mcp'    joint='L_thumb_mcp_joint'    noise='0' />
    <jointvel name='jointvel_L_thumb_roll'   joint='L_thumb_roll_joint'   noise='0' />
    <jointvel name='jointvel_L_thumb_abad'   joint='L_thumb_abad_joint'   noise='0' />
    <jointvel name='jointvel_L_index_abad'   joint='L_index_abad_joint'   noise='0' />
    <jointvel name='jointvel_L_index_pip'    joint='L_index_pip_joint'    noise='0' />
    <jointvel name='jointvel_L_middle_pip'   joint='L_middle_pip_joint'   noise='0' />
    <jointvel name='jointvel_L_ring_abad'    joint='L_ring_abad_joint'    noise='0' />
    <jointvel name='jointvel_L_ring_pip'     joint='L_ring_pip_joint'     noise='0' />
    <jointvel name='jointvel_L_pinky_abad'   joint='L_pinky_abad_joint'   noise='0' />
    <jointvel name='jointvel_L_pinky_pip'    joint='L_pinky_pip_joint'    noise='0' />

    <jointvel name='jointvel_R_thumb_mcp'    joint='R_thumb_mcp_joint'    noise='0' />
    <jointvel name='jointvel_R_thumb_roll'   joint='R_thumb_roll_joint'   noise='0' />
    <jointvel name='jointvel_R_thumb_abad'   joint='R_thumb_abad_joint'   noise='0' />
    <jointvel name='jointvel_R_index_abad'   joint='R_index_abad_joint'   noise='0' />
    <jointvel name='jointvel_R_index_pip'    joint='R_index_pip_joint'    noise='0' />
    <jointvel name='jointvel_R_middle_pip'   joint='R_middle_pip_joint'   noise='0' />
    <jointvel name='jointvel_R_ring_abad'    joint='R_ring_abad_joint'    noise='0' />
    <jointvel name='jointvel_R_ring_pip'     joint='R_ring_pip_joint'     noise='0' />
    <jointvel name='jointvel_R_pinky_abad'   joint='R_pinky_abad_joint'   noise='0' />
    <jointvel name='jointvel_R_pinky_pip'    joint='R_pinky_pip_joint'    noise='0' />

    <!-- 左手 position -->
    <jointpos name='jointpos_L_thumb_mcp_joint'   joint='L_thumb_mcp_joint'   noise='0' />
    <jointpos name='jointpos_L_thumb_roll_joint'  joint='L_thumb_roll_joint'  noise='0' />
    <jointpos name='jointpos_L_thumb_abad_joint'  joint='L_thumb_abad_joint'  noise='0' />
    <jointpos name='jointpos_L_index_abad_joint'  joint='L_index_abad_joint'  noise='0' />
    <jointpos name='jointpos_L_index_pip_joint'   joint='L_index_pip_joint'   noise='0' />
    <jointpos name='jointpos_L_middle_pip_joint'  joint='L_middle_pip_joint'  noise='0' />
    <jointpos name='jointpos_L_ring_abad_joint'   joint='L_ring_abad_joint'   noise='0' />
    <jointpos name='jointpos_L_ring_pip_joint'    joint='L_ring_pip_joint'    noise='0' />
    <jointpos name='jointpos_L_pinky_abad_joint'  joint='L_pinky_abad_joint'  noise='0' />
    <jointpos name='jointpos_L_pinky_pip_joint'   joint='L_pinky_pip_joint'   noise='0' />

    <!-- 右手 position -->
    <jointpos name='jointpos_R_thumb_mcp_joint'   joint='R_thumb_mcp_joint'   noise='0' />
    <jointpos name='jointpos_R_thumb_roll_joint'  joint='R_thumb_roll_joint'  noise='0' />
    <jointpos name='jointpos_R_thumb_abad_joint'  joint='R_thumb_abad_joint'  noise='0' />
    <jointpos name='jointpos_R_index_abad_joint'  joint='R_index_abad_joint'  noise='0' />
    <jointpos name='jointpos_R_index_pip_joint'   joint='R_index_pip_joint'   noise='0' />
    <jointpos name='jointpos_R_middle_pip_joint'  joint='R_middle_pip_joint'  noise='0' />
    <jointpos name='jointpos_R_ring_abad_joint'   joint='R_ring_abad_joint'   noise='0' />
    <jointpos name='jointpos_R_ring_pip_joint'    joint='R_ring_pip_joint'    noise='0' />
    <jointpos name='jointpos_R_pinky_abad_joint'  joint='R_pinky_abad_joint'  noise='0' />
    <jointpos name='jointpos_R_pinky_pip_joint'   joint='R_pinky_pip_joint'   noise='0' />

  </sensor>
</mujoco>
